Workbook
Name Cliente: [1]!Clientes[Código do Cliente]
Name COD_ENTRADA: #REF!
Name COD_ESTOQUE: #REF!
Name COD_QUANTIDADE: #REF!
Name COD_SAÍDA: #REF!
Name ESTOQUE: #REF!
Name Fornecedor: [1]!Fornecedores[Código do Fornecedor]
Name Item: [1]!Itens[Código do Item]
Name Local: [1]!Locais[Local]
Name Unidade: [1]!Unidades[Unidade]

Sheet Apresentação
B2: Entra21 2026
B4: Parametrização | D4: Markup | F4: DRE - PREVISTO
B6: Análise do Preço de Compras | D6: Simulador de Preços de Venda | F6: Fluxo de Caixa Mensal
B8: Encargos Sociais Trabalhistas | D8: Distribuição do Recebimento | F8: Ficha Técnica
B10: SIMPLES | D10: TABELA DO MEI - 2026 | F10: Ponto de Equilibrio
F12: Movimento de Caixa

Sheet Ponto de Equilibrio
A1: h
B4: Quantidades | D4: ='DRE PREVISTO'!AA7 -> 59500 | E4: % | G4: =IFERROR((G6/G5),0) -> 90186.489 | H4: % | J4: 0 | K4: %
B5: Preço Médio Unitário - R$ | D5: =+'DRE PREVISTO'!AA8 -> 10 | G5: =D5 -> 10 | J5: 0
B6: Faturamento (Qtde. x Preço Médio) | D6: =D4*D5 -> 595000 | E6: =IFERROR((D6/$D$6),0) -> 1 | G6: =(SUM(G14:G17)+J21)/(1-F7-F9-F10-F12-H21) -> 901864.89 | H6: =IFERROR((G6/$G$6),0) -> 1 | J6: =J4*J5 -> 0 | K6: =IFERROR((J6/$J$6),0) -> 0
B7: (-) Impostos sobre Vendas | C7: ='DRE PREVISTO'!B10 -> 0.071705882 | D7: =D6*C7 -> 42665 | E7: =IFERROR((D7/$D$6),0) -> 0.071705882 | F7: =+C7 -> 0.071705882 | G7: =G6*F7 -> 64669.018 | H7: =IFERROR((G7/$G$6),0) -> 0.071705882 | I7: 0 | J7: =J6*I7 -> 0 | K7: =IFERROR((J7/$J$6),0) -> 0
B8: (=) Receita Líquida (Faturamento - Imposto) | D8: =D6-D7 -> 552335 | E8: =IFERROR((D8/$D$6),0) -> 0.92829412 | G8: =G6-G7 -> 837195.87 | H8: =IFERROR((G8/$G$6),0) -> 0.92829412 | J8: =J6-J7 -> 0 | K8: =IFERROR((J8/$J$6),0) -> 0
B9: (-) Custo das Mercadorias/Produto | C9: ='DRE PREVISTO'!B18 -> 0.4 | D9: =D6*C9 -> 238000 | E9: =IFERROR((D9/$D$6),0) -> 0.4 | F9: =+C9 -> 0.4 | G9: =G6*F9 -> 360745.96 | H9: =IFERROR((G9/$G$6),0) -> 0.4 | I9: 0 | J9: =J6*I9 -> 0 | K9: =IFERROR((J9/$J$6),0) -> 0
B10: (-) Custo da Mão de Obra Direta | C10: ='DRE PREVISTO'!B19+'DRE PREVISTO'!B20 -> 0 | D10: =D6*C10 -> 0 | E10: =IFERROR((D10/$D$6),0) -> 0 | F10: =+C10 -> 0 | G10: =G6*F10 -> 0 | H10: =IFERROR((G10/$G$6),0) -> 0 | I10: 0 | J10: =J6*I10 -> 0 | K10: =IFERROR((J10/$J$6),0) -> 0
B11: (=) Lucro Bruto (Receita Líquida - Custos) | D11: =D8-D9-D10 -> 314335 | E11: =IFERROR((D11/$D$6),0) -> 0.52829412 | G11: =G8-G9-G10 -> 476449.92 | H11: =IFERROR((G11/$G$6),0) -> 0.52829412 | J11: =J8-J9-J10 -> 0 | K11: =IFERROR((J11/$J$6),0) -> 0
B12: (-) Comissão/Frete (Gastos variáveis) | C12: =+'DRE PREVISTO'!B31 -> 0.08 | D12: =D6*C12 -> 47600 | E12: =IFERROR((D12/$D$6),0) -> 0.08 | F12: =+C12 -> 0.08 | G12: =G6*F12 -> 72149.191 | H12: =IFERROR((G12/$G$6),0) -> 0.08 | I12: 0 | J12: =J6*I12 -> 0 | K12: =IFERROR((J12/$J$6),0) -> 0
B13: (=) Margem de Contribuição (Lucro Bruto - Gastos Variáveis) | D13: =D11-D12 -> 266735 | E13: =IFERROR((D13/$D$6),0) -> 0.44829412 | G13: =G11-G12 -> 404300.73 | H13: =IFERROR((G13/$G$6),0) -> 0.44829412 | J13: =J11-J12 -> 0 | K13: =IFERROR((J13/$J$6),0) -> 0
B14: (-) Despesas Administrativas (Fixas) | D14: =+'DRE PREVISTO'!AA36 -> 269020.99 | E14: =IFERROR((D14/$D$6),0) -> 0.45213612 | G14: =D14 -> 269020.99 | H14: =IFERROR((G14/$G$6),0) -> 0.29829412 | J14: =+G14 -> 269020.99 | K14: =IFERROR((J14/$J$6),0) -> 0
B15: (-) Custos Indiretos de Fabricação (Fixo) | D15: =+'DRE PREVISTO'!AA21 -> 0 | G15: =D15 -> 0 | J15: 0 | K15: =IFERROR((J15/$J$6),0) -> 0
B16: (-) Despesas Comerciais (Fixas) | G16: =D16 -> 0 | K16: =IFERROR((J16/$J$6),0) -> 0
B17: (-) Despesas Financeiras (Fixas) | D17: =+'DRE PREVISTO'!AA63 -> 0 | E17: =IFERROR((D17/$D$6),0) -> 0 | G17: =D17 -> 0 | H17: =IFERROR((G17/$G$6),0) -> 0 | K17: =IFERROR((J17/$J$6),0) -> 0
B18: (=) Resultado Líquido | D18: =D13-SUM(D14:D17) -> -2285.992 | E18: =IFERROR((D18/$D$6),0) -> -0.0038420034 | G18: =G13-SUM(G14:G17) -> 135279.73 | H18: =IFERROR((G18/$G$6),0) -> 0.15 | J18: =J13-SUM(J14:J17) -> -269020.99 | K18: =IFERROR((J18/$J$6),0) -> 0
D19: =+'DRE PREVISTO'!AA64-D18 -> 0
H21: 0.15 | I21: Valor | J21: 0

Sheet Movimento de Caixa
B1: MOVIMENTO DE CAIXA
B3: PERÍODO | C3: HISTÓRICO | D3: ENTRADAS | E3: SAÍDAS | F3: SALDO
F4: 0
F5: =F4+D5-E5 -> 0
F6: =F5+D6-E6 -> 0
F7: =F6+D7-E7 -> 0
F8: =F7+D8-E8 -> 0
F9: =F8+D9-E9 -> 0
F10: =F9+D10-E10 -> 0
F11: =F10+D11-E11 -> 0
F12: =F11+D12-E12 -> 0
F13: =F12+D13-E13 -> 0
F14: =F13+D14-E14 -> 0
F15: =F14+D15-E15 -> 0
F16: =F15+D16-E16 -> 0
... F40: =F39+D40-E40 -> 0
B41: TOTAL
C42: Saldo Inicial | F42: =F4 -> 0
C43: Total de Entradas | D43: =SUM(D4:D40) -> 0
C44: Total de Saídas | E44: =SUM(E4:E40) -> 0
C45: Saldo Final | F45: =F42+D43-E44 -> 0

Sheet Simulador
A1: SIMULADOR DE PREÇOS
A2: Referencia | C2: DESCRIÇÃO DO PRODUTO | F2: Bolsa
A3: CUSTO DO PRODUTO (R$) | I3: 4
A4: Preço Calculado | F4: Preço de Mercado
A5: Condições de Pagamento | D5: Markup | E5: R$ | F5: Condições de Pagamento | H5: Prazo | I5: R$
A6: À Vista | B6: Dias | C6: 60 | D6: =(((((1+$E$9)/(1-(+$E$12+$E$17+$E$23+$E$7+($E$22*(1-($E$13+$E$14+$E$15+$E$16)))))*((1+$D$8)^($C$6/30)))/(1-$E$10)))) -> 2.9334116 | E6: =I3*D6 -> 11.733646 | F6: À Vista (1) | G6: Dias | H6: 60 | I6: 10
A7: Lucro | E7: 0.15 | F7: Lucro | I7: =I33 -> 0.0909
A8: Taxa Financeira | D8: 0 | E8: a.m. | F8: PREÇO BRUTO | G8: 1 | H8: =IF(G8=1,I6,IF(G8=2,#REF!,#REF!)) -> 10 | I8: =H8/H10 -> 1
A9: Imperfeitos | E9: 0 | F9: =A10 -> Bonificação | H9: =H8*I9 -> 0 | I9: =+E10 -> 0
A10: Bonificação | E10: 0 | F10: PREÇO LIQUIDO DE VENDA | H10: =+H8-H9 -> 10 | I10: =H10/H10 -> 1
A11: Despesas Variáveis de Venda | E11: =E12+E17+E23 -> 0.5091 | F11: Impostos | H11: =SUM(H12:H15) -> 0.713 | I11: =H11/H10 -> 0.0713
A12: Impostos | E12: =SUM(E13:E16) -> 0.0713 | F12: =A13 -> ICMS | H12: =$H$10*I12 -> 0 | I12: =E13 -> 0
A13: ICMS | E13: 0 | F13: =A14 -> PIS | H13: =$H$10*I13 -> 0 | I13: =E14 -> 0
A14: PIS | E14: 0 | F14: =A15 -> COFINS | H14: =$H$10*I14 -> 0 | I14: =E15 -> 0
A15: COFINS | E15: 0 | F15: =A16 -> Simples | H15: =$H$10*I15 -> 0.713 | I15: =E16 -> 0.0713
A16: Simples | E16: 0.0713 | F16: PREÇO LÍQUIDO | H16: =+H10-H11 -> 9.287 | I16: =+H16/H10 -> 0.9287
A17: Despesas Comerciais Variáveis | E17: =SUM(E18:E21) -> 0.08 | F17: CUSTO DO PRODUTO | H17: =+I3 -> 4 | I17: =H17/H10 -> 0.4
A18: Cartão de Crédito | E18: 0.03 | F18: =A9 -> Imperfeitos | H18: =+H17*I18 -> 0 | I18: =E9 -> 0
A19: Frete | E19: 0 | F19: MARGEM BRUTA | H19: =H16-H17-H18 -> 5.287 | I19: =H19/H10 -> 0.5287
A20: Comissão | E20: 0.05 | F20: Desps Com Variáveis | H20: =SUM(H21:H25) -> 0.8 | I20: =H20/H10 -> 0.08
A21: Prov. Dev Duv | E21: 0 | F21: =A18 -> Cartão de Crédito | H21: =$H$10*I21 -> 0.3 | I21: =E18 -> 0.03
A22: Royalties | E22: 0 | F22: =A19 -> Frete | H22: =$H$10*I22 -> 0 | I22: =E19 -> 0
A23: Outras Despesas | E23: =SUM(E24:E26) -> 0.3578 | F23: =A20 -> Comissão | H23: =$H$10*I23 -> 0.5 | I23: =E20 -> 0.05
A24: Despesa Fixa | E24: 0.3578 | F24: =A21 -> Prov. Dev Duv | H24: =$H$10*I24 -> 0 | I24: =E21 -> 0
E25: 0 | F25: =A22 -> Royalties | H25: =H10*(I25*(1-I12-I13-I14-I15)) -> 0 | I25: =E22 -> 0
E26: 0 | F26: MARGEM OPERACIONAL | H26: =H19-H20 -> 4.487 | I26: =H26/H10 -> 0.4487
F27: =A24 -> Despesa Fixa | H27: =$H$10*I27 -> 3.578 | I27: =E24 -> 0.3578
F28: =A25 | H28: =$H$10*I28 -> 0 | I28: =E25 -> 0
F29: =A26 | H29: =$H$10*I29 -> 0 | I29: =E26 -> 0
F30: MARGEM LIQUIDA | H30: =H26-H27-H28-H29 -> 0.909 | I30: =H30/H10 -> 0.0909
F31: DESPESA FINANCEIRA | H31: =H32 -> 0 | I31: =H31/H10 -> 0
F32: Despesa Financeira | H32: =IF(G8=1,(H17+H18)*(((1+D8)^((H6)/30))-1),(H17+H18)*(((1+D8)^((#REF!*30)/30))-1)) -> 0 | I32: =E28 -> 0
F33: LUCRO LÍQUIDO | H33: =H30-H31 -> 0.909 | I33: =H33/H10 -> 0.0909

Sheet Markup
A1: FORMAÇÃO DO MARK-UP
A2: MARK-UP | B2: REFERENCIAS
B3: Cosmetico | C3: Acessorios | D3: Bolsas | E3: Promocional | F3: Outros
A4: Imperfeitos | B4: 0 | C4: 0 | D4: 0 | E4: 0 | F4: 0
A5: Taxa Financeira | B5: 0 | C5: 0 | D5: 0 | E5: 0 | F5: 0
A6: Bonificação | B6: 0 | C6: 0 | D6: 0.05 | E6: 0 | F6: 0
A7: Prazo de Médio de Venda | B7: 60 | C7: 60 | D7: 60 | E7: 60 | F7: 60
A8: Despesa Fixa | B8: 0.3578 | C8: 0.3578 | D8: 0.3578 | E8: 0.3578 | F8: 0.3578
A9: Frete | B9: 0 | C9: 0 | D9: 0 | E9: 0 | F9: 0
A10: Comissão | B10: 0.05 | C10: 0.05 | D10: 0.05 | E10: 0.05 | F10: 0.05
A11: Prov. P/Dev. Duvidosos | B11: 0 | C11: 0 | D11: 0 | E11: 0 | F11: 0
A12: Cartão de Crédito | B12: 0.03 | C12: 0.03 | D12: 0.03 | E12: 0.03 | F12: 0.03
A13: Royalties | B13: 0 | C13: 0 | D13: 0 | E13: 0 | F13: 0
A14: ICMS | B14: 0 | C14: 0 | D14: 0 | E14: 0 | F14: 0
A15: PIS | B15: 0 | C15: 0 | D15: 0 | E15: 0 | F15: 0
... A20: Lucro | B20: 0.1 | C20: 0.15 | D20: 0.2 | E20: 0.25 | F20: 0.3
A21: Markup | B21: =(((((1+B4)/(1-(+B8+B9+B10+B11+B12+B13+B14+B15+B16+B17+B18+B19+B20+(B13*(1-(B14+B15+B16+B19)))))*((1+B5)^(B7/30))))))/(1-B6) -> 2.5562372 | C21: =(((((1+C4)/(1-(+C8+C9+C10+C11+C12+C13+C14+C15+C16+C17+C18+C19+C20+(C13*(1-(C14+C15+C16+C19)))))*((1+C5)^(C7/30))))))/(1-C6) -> 2.9308324 | D21: =(((((1+D4)/(1-(+D8+D9+D10+D11+D12+D13+D14+D15+D16+D17+D18+D19+D20+(D13*(1-(D14+D15+D16+D19)))))*((1+D5)^(D7/30))))))/(1-D6) -> 3.6148062 | E21: =(((((1+E4)/(1-(+E8+E9+E10+E11+E12+E13+E14+E15+E16+E17+E18+E19+E20+(E13*(1-(E14+E15+E16+E19)))))*((1+E5)^(E7/30))))))/(1-E6) -> 4.145937 | F21: =(((((1+F4)/(1-(+F8+F9+F10+F11+F12+F13+F14+F15+F16+F17+F18+F19+F20+(F13*(1-(F14+F15+F16+F19)))))*((1+F5)^(F7/30))))))/(1-F6) -> 5.2301255
B22: 4 | C22: 4 | D22: 4 | E22: 4 | F22: 4
B23: =+B21*B22 -> 10.224949 | C23: =+C21*C22 -> 11.723329 | D23: =+D21*D22 -> 14.459225 | E23: =+E21*E22 -> 16.583748 | F23: =+F21*F22 -> 20.920502

Sheet Encargos 
A1: 6
A2: 1) OBRIGAÇÕES PREVIDÊNCIARIAS | B2: MEI | C2: EPP | D2: SIMPLES | E2: COMÉRCIO | F2: INDÚSTRIA | G2: SOCIOS
A3: INSS | B3: 0.03 | C3: 0.055 | D3: 0 | E3: 0.2 | F3: 0.2 | G3: 0.2
A4: SESC | B4: 0 | C4: 0 | D4: 0 | E4: 0.01 | F4: 0 | G4: 0
A5: SENAC | B5: 0 | C5: 0 | D5: 0 | E5: 0.015 | F5: 0 | G5: 0
A6: SENAI | B6: 0 | C6: 0 | D6: 0 | E6: 0 | F6: 0.01 | G6: 0
A7: SESI | B7: 0 | C7: 0 | D7: 0 | E7: 0 | F7: 0.015 | G7: 0
A8: INCRA | B8: 0 | C8: 0 | D8: 0 | E8: 0.002 | F8: 0.002 | G8: 0
A9: SEBRAE | B9: 0 | C9: 0 | D9: 0 | E9: 0.003 | F9: 0.003 | G9: 0
A10: SALÁRIO EDUCAÇÃO | B10: 0 | C10: 0 | D10: 0 | E10: 0.025 | F10: 0.025 | G10: 0
A11: SAT SEGURO ACIDENTES TRABALHO | B11: 0 | C11: 0 | D11: 0 | E11: 0.01 | F11: 0.01 | G11: 0
A12: SUB-TOTAL | B12: =SUM(B3:B11) -> 0.03 | C12: =SUM(C3:C11) -> 0.055 | D12: =SUM(D3:D11) -> 0 | E12: =SUM(E3:E11) -> 0.265 | F12: =SUM(F3:F11) -> 0.265 | G12: =SUM(G3:G11) -> 0.2
A13: 2) 13 SALÁRIO
A14: 13º SALÁRIO | B14: =1/12 -> 0.083333333 | C14: =1/12 -> 0.083333333 | D14: =1/12 -> 0.083333333 | E14: =1/12 -> 0.083333333 | F14: =1/12 -> 0.083333333 | G14: 0
A15: SUB-TOTAL | B15: =SUM(B14:B14) -> 0.083333333 | C15: =SUM(C14:C14) -> 0.083333333 | D15: =SUM(D14:D14) -> 0.083333333 | E15: =SUM(E14:E14) -> 0.083333333 | F15: =SUM(F14:F14) -> 0.083333333 | G15: =SUM(G14:G14) -> 0
A16: 3) FÉRIAS
A17: FÉRIAS | B17: =1/12 -> 0.083333333 | C17: =1/12 -> 0.083333333 | D17: =1/12 -> 0.083333333 | E17: =1/12 -> 0.083333333 | F17: =1/12 -> 0.083333333 | G17: 0
A18: ADICIONAL DE FÉRIAS (33%) | B18: =B17*33% -> 0.0275 | C18: =C17*33% -> 0.0275 | D18: =D17*33% -> 0.0275 | E18: =E17*33% -> 0.0275 | F18: =F17*33% -> 0.0275 | G18: =G17*33% -> 0
A19: SUB-TOTAL | B19: =SUM(B17:B18) -> 0.11083333 | C19: =SUM(C17:C18) -> 0.11083333 | D19: =SUM(D17:D18) -> 0.11083333 | E19: =SUM(E17:E18) -> 0.11083333 | F19: =SUM(F17:F18) -> 0.11083333 | G19: =SUM(G17:G18) -> 0
A20: 4) FGTS
A21: FGTS | B21: 0.08 | C21: 0.08 | D21: 0.08 | E21: 0.08 | F21: 0.08 | G21: 0
A22: SUB-TOTAL | B22: =SUM(B21:B21) -> 0.08 | C22: =SUM(C21:C21) -> 0.08 | D22: =SUM(D21:D21) -> 0.08 | E22: =SUM(E21:E21) -> 0.08 | F22: =SUM(F21:F21) -> 0.08 | G22: =SUM(G21:G21) -> 0
A23: 5) REINCIDENCIAS INSS
A24: S/13 º SALARIO | B24: =+B15*B12 -> 0.0025 | C24: =+C15*C12 -> 0.0045833333 | D24: =+D15*D12 -> 0 | E24: =+E15*E12 -> 0.022083333 | F24: =+F15*F12 -> 0.022083333 | G24: =+G15*G12 -> 0
A25: S/ FÉRIAS | B25: =+B19*B12 -> 0.003325 | C25: =+C19*C12 -> 0.0060958333 | D25: =+D19*D12 -> 0 | E25: =+E19*E12 -> 0.029370833 | F25: =+F19*F12 -> 0.029370833 | G25: =+G19*G12 -> 0
A26: SUB-TOTAL | B26: =SUM(B24:B25) -> 0.005825 | C26: =SUM(C24:C25) -> 0.010679167 | D26: =SUM(D24:D25) -> 0 | E26: =SUM(E24:E25) -> 0.051454167 | F26: =SUM(F24:F25) -> 0.051454167 | G26: =SUM(G24:G25) -> 0
A27: 6) REINCIDENCIAS FGTS
A28: S/13º SALARIO | B28: =+B15*B22 -> 0.0066666667 | C28: =+C15*C22 -> 0.0066666667 | D28: =+D15*D22 -> 0.0066666667 | E28: =+E15*E22 -> 0.0066666667 | F28: =+F15*F22 -> 0.0066666667 | G28: =+G15*G22 -> 0
A29: S/FÉRIAS | B29: =+B19*B22 -> 0.0088666667 | C29: =+C19*C22 -> 0.0088666667 | D29: =+D19*D22 -> 0.0088666667 | E29: =+E19*E22 -> 0.0088666667 | F29: =+F19*F22 -> 0.0088666667 | G29: =+G19*G22 -> 0
A30: SUB-TOTAL | B30: =SUM(B28:B29) -> 0.015533333 | C30: =SUM(C28:C29) -> 0.015533333 | D30: =SUM(D28:D29) -> 0.015533333 | E30: =SUM(E28:E29) -> 0.015533333 | F30: =SUM(F28:F29) -> 0.015533333 | G30: =SUM(G28:G29) -> 0
A31: RECISÕES TRABALHISTAS | B31: 0 | C31: 0 | D31: 0 | E31: 0 | F31: 0 | G31: 0
A32: PERICULOSIDADE | B32: 0 | C32: 0 | D32: 0 | E32: 0 | F32: 0 | G32: 0
A33: BENEFICIOS - Encargos Assistenciais | B33: 0 | C33: 0 | D33: 0 | E33: 0 | F33: 0 | G33: 0
A34: TOTAL | B34: =+B12+B15+B19+B22+B26+B30+B31+B32+B33 -> 0.325525 | C34: =+C12+C15+C19+C22+C26+C30+C31+C32+C33 -> 0.35537917 | D34: =+D12+D15+D19+D22+D26+D30+D31+D32+D33 -> 0.2897 | E34: =+E12+E15+E19+E22+E26+E30+E31+E32+E33 -> 0.60615417 | F34: =+F12+F15+F19+F22+F26+F30+F31+F32+F33 -> 0.60615417 | G34: =+G12+G15+G19+G22+G26+G30+G31+G32+G33 -> 0.2
A36: Forma Jurídica da empresa | E36: 3 | F36: =IF(E36=1,B34,IF(E36=2,C34,IF(E36=3,D34,IF(E36=4,E34,IF(E36=5,F34,IF(E36=6,G34)))))) -> 0.2897
A37: 1 -MEI
A38: 2 - EPP
A39: 3 - Simples
A40: 4 - Comércio
A41: 5 - Indústria
...

Sheet MEI
B2: TABELA PARA MEI - 2026 Em R$
B3: Atividade MEI | C3: INSS | D3: ICMS/ISS | E3: Valor mensal do DAS
B4: Comércio e Indústria – ICMS | C4: 81.05 | D4: 1 | E4: =+C4+D4 -> 82.05
B5: Serviços – ISS | C5: 81.05 | D5: 5 | E5: =+C5+D5 -> 86.05
B6: Comércio e Serviços – ICMS e ISS | C6: 81.05 | D6: 6 | E6: =+C6+D6 -> 87.05

Sheet SIMPLES
A1: LEI COMPLEMENTAR Nº 155, DE 27 DE OUTUBRO DE 2016
A3: Alíquotas e Partilha do Simples Nacional – Comércio
A5: Receita Bruta em 12 Meses (em R$) | C5: Alíquota | D5: Valor a Deduzir (em R$)
A6: 1a Faixa | B6: Até 180.000,00 | C6: 0.04 | D6: 0
A7: 2a Faixa | B7: De 180.000,01 a 360.000,00 | C7: 0.073 | D7: 5940 | F7: Faturamento | G7: % Simples | H7: Imposto | I7: Vlr a Deduzir | J7: Imposto a pagar | K7: %
A8: 3a Faixa | B8: De 360.000,01 a 720.000,00 | C8: 0.095 | D8: 13860 | F8: ='DRE PREVISTO'!AA9 -> 595000 | G8: =+C8 -> 0.095 | H8: =F8*G8 -> 56525 | I8: =+D8 -> 13860 | J8: =H8-I8 -> 42665 | K8: =IFERROR((J8/F8),0) -> 0.071705882
A9: 4a Faixa | B9: De 720.000,01 a 1.800.000,00 | C9: 0.107 | D9: 22500
A10: 5a Faixa | B10: De 1.800.000,01 a 3.600.000,00 | C10: 0.143 | D10: 87300
A11: 6a Faixa | B11: De 3.600.000,01 a 4.800.000,00 | C11: 0.19 | D11: 378000
A13: Alíquotas e Partilha do Simples Nacional – Indústria
A15: Receita Bruta em 12 Meses (em R$) | C15: Alíquota | D15: Valor a Deduzir (em R$)
A16: 1a Faixa | B16: Até 180.000,00 | C16: 0.045 | D16: -
A17: 2a Faixa | B17: De 180.000,01 a 360.000,00 | C17: 0.078 | D17: 5940
A18: 3a Faixa | B18: De 360.000,01 a 720.000,00 | C18: 0.1 | D18: 13860
A19: 4a Faixa | B19: De 720.000,01 a 1.800.000,00 | C19: 0.112 | D19: 22500
A20: 5a Faixa | B20: De 1.800.000,01 a 3.600.000,00 | C20: 0.147 | D20: 85500
A21: 6a Faixa | B21: De 3.600.000,01 a 4.800.000,00 | C21: 0.3 | D21: 720000
A23: Alíquotas e Partilha do Simples Nacional - Receitas de locação de bens móveis e de prestação de serviços não relacionados no § 5o-C do art. 18 desta Lei Complementar
A25: Receita Bruta em 12 Meses (em R$) | C25: Alíquota | D25: Valor a Deduzir (em R$)
A26: 1a Faixa | B26: Até 180.000,00 | C26: 0.06 | D26: –
A27: 2a Faixa | B27: De 180.000,01 a 360.000,00 | C27: 0.112 | D27: 9360
A28: 3a Faixa | B28: De 360.000,01 a 720.000,00 | C28: 0.135 | D28: 17640
A29: 4a Faixa | B29: De 720.000,01 a 1.800.000,00 | C29: 0.16 | D29: 35640
A30: 5a Faixa | B30: De 1.800.000,01 a 3.600.000,00 | C30: 0.21 | D30: 125640
A31: 6a Faixa | B31: De 3.600.000,01 a 4.800.000,00 | C31: 0.33 | D31: 648000
A33: Alíquotas e Partilha do Simples Nacional – Receitas decorrentes da prestação de serviços relacionados no § 5o-C do art. 18 desta Lei Complementar
A35: Receita Bruta em 12 Meses (em R$) | C35: Alíquota | D35: Valor a Deduzir (em R$)
A36: 1a Faixa | B36: Até 180.000,00 | C36: 0.045 | D36: -
A37: 2a Faixa | B37: De 180.000,01 a 360.000,00 | C37: 0.09 | D37: 8100
A38: 3a Faixa | B38: De 360.000,01 a 720.000,00 | C38: 0.102 | D38: 12420
A39: 4a Faixa | B39: De 720.000,01 a 1.800.000,00 | C39: 0.14 | D39: 39780
A40: 5a Faixa | B40: De 1.800.000,01 a 3.600.000,00 | C40: 0.22 | D40: 183780
A41: 6a Faixa | B41: De 3.600.000,01 a 4.800.000,00 | C41: 0.33 | D41: 828000
A43: Alíquotas e Partilha do Simples Nacional - Receitas decorrentes da prestação de serviços relacionados no § 5o-I do art. 18 desta Lei Complementar
A45: Receita Bruta em 12 Meses (em R$) | C45: Alíquota | D45: Valor a Deduzir (em R$)
A46: 1a Faixa | B46: Até 180.000,00 | C46: 0.155 | D46: -
A47: 2a Faixa | B47: De 180.000,01 a 360.000,00 | C47: 0.18 | D47: 4500
A48: 3a Faixa | B48: De 360.000,01 a 720.000,00 | C48: 0.195 | D48: 9900
A49: 4a Faixa | B49: De 720.000,01 a 1.800.000,00 | C49: 0.205 | D49: 17100
A50: 5a Faixa | B50: De 1.800.000,01 a 3.600.000,00 | C50: 0.23 | D50: 62100
...

Sheet Distribuição do Recebimento
A1: DISTRIBUIÇÃO DO RECEBIMENTO
A2: Prazos Recebim | B2: Dias | C2: % | D2: Prazo Médio
A3: A VISTA | B3: 0 | C3: 0.3 | D3: =+B3*C3 -> 0
A4: 30 DIAS | B4: 30 | C4: 0.4 | D4: =+B4*C4 -> 12
A5: 60 DIAS | B5: 60 | C5: 0.3 | D5: =+B5*C5 -> 18
A6: 90 DIAS | B6: 90 | C6: 0 | D6: =+B6*C6 -> 0
A7: 120 DIAS | B7: 120 | C7: 0 | D7: =+B7*C7 -> 0
A8: 150 DIAs | B8: 150 | C8: 0 | D8: =+B8*C8 -> 0
A9: 180 dias | B9: 180 | C9: 0 | D9: =+B9*C9 -> 0
A10: TOTAL | C10: =SUM(C3:C9) -> 1 | D10: =SUM(D3:D9) -> 30
A11: DISTRIBUIÇÃO DE RECEBIMENTO - ORÇADO
B12: REC BRUTA | C12: PDD | D12: LÍQUIDO | E12: =$A$18 -> 46023 | F12: =$A$19 -> 46054 | G12: =$A$20 -> 46082 | H12: =$A$21 -> 46113 | I12: =$A$22 -> 46143 | J12: =$A$23 -> 46174 | K12: =$A$24 -> 46204 | L12: =$A$25 -> 46235 | M12: =$A$26 -> 46266 | N12: =$A$27 -> 46296 | O12: =$A$28 -> 46327 | P12: =$A$29 -> 46357 | Q12: TOTAL
A13: =A14-30 -> 45873 | B13: 50000 | C13: 0 | D13: =+B13+C13 -> 50000 | E13: =$D13*$C$8 -> 0 | F13: =$D13*$C$9 -> 0 | Q13: =SUM(E13:P13) -> 0
A14: =A15-30 -> 45903 | B14: 50000 | C14: 0 | D14: =+B14+C14 -> 50000 | E14: =$D14*$C$7 -> 0 | F14: =$D14*$C$8 -> 0 | G14: =$D14*$C$9 -> 0 | Q14: =SUM(E14:P14) -> 0
A15: =A16-30 -> 45933 | B15: 50000 | C15: 0 | D15: =+B15+C15 -> 50000 | E15: =$D15*$C$6 -> 0 | F15: =$D15*$C$7 -> 0 | G15: =$D15*$C$8 -> 0 | H15: =$D15*$C$9 -> 0 | Q15: =SUM(E15:P15) -> 0
A16: =A17-30 -> 45963 | B16: 50000 | C16: 0 | D16: =+B16+C16 -> 50000 | E16: =$D16*$C$5 -> 15000 | F16: =$D16*$C$6 -> 0 | G16: =$D16*$C$7 -> 0 | H16: =$D16*$C$8 -> 0 | I16: =$D16*$C$9 -> 0 | Q16: =SUM(E16:P16) -> 15000
A17: =A18-30 -> 45993 | B17: 50000 | C17: 0 | D17: =+B17+C17 -> 50000 | E17: =$D17*$C$4 -> 20000 | F17: =$D17*$C$5 -> 15000 | G17: =$D17*$C$6 -> 0 | H17: =$D17*$C$7 -> 0 | I17: =$D17*$C$8 -> 0 | J17: =$D17*$C$9 -> 0 | Q17: =SUM(E17:P17) -> 35000
A18: =Parametrização!F3 -> 46023 | B18: ='DRE PREVISTO'!$C$9 -> 40000 | C18: 0 | D18: =+B18+C18 -> 40000 | E18: =$D18*$C$3 -> 12000 | F18: =$D18*$C$4 -> 16000 | G18: =$D18*$C$5 -> 12000 | H18: =$D18*$C$6 -> 0 | I18: =$D18*$C$7 -> 0 | J18: =$D18*$C$8 -> 0 | K18: =$D18*$C$9 -> 0 | Q18: =SUM(E18:P18) -> 40000
A19: =Parametrização!F4 -> 46054 | B19: ='DRE PREVISTO'!$E$9 -> 45000 | C19: 0 | D19: =+B19+C19 -> 45000 | F19: =$D19*$C$3 -> 13500 | G19: =$D19*$C$4 -> 18000 | H19: =$D19*$C$5 -> 13500 | I19: =$D19*$C$6 -> 0 | J19: =$D19*$C$7 -> 0 | K19: =$D19*$C$8 -> 0 | L19: =$D19*$C$9 -> 0 | Q19: =SUM(E19:P19) -> 45000
A20: =Parametrização!F5 -> 46082 | B20: ='DRE PREVISTO'!$G$9 -> 50000 | C20: 0 | D20: =+B20+C20 -> 50000 | G20: =$D20*$C$3 -> 15000 | H20: =$D20*$C$4 -> 20000 | I20: =$D20*$C$5 -> 15000 | J20: =$D20*$C$6 -> 0 | K20: =$D20*$C$7 -> 0 | L20: =$D20*$C$8 -> 0 | M20: =$D20*$C$9 -> 0 | Q20: =SUM(E20:P20) -> 50000
A21: =Parametrização!F6 -> 46113 | B21: ='DRE PREVISTO'!$I$9 -> 50000 | C21: 0 | D21: =+B21+C21 -> 50000 | H21: =$D21*$C$3 -> 15000 | I21: =$D21*$C$4 -> 20000 | J21: =$D21*$C$5 -> 15000 | K21: =$D21*$C$6 -> 0 | L21: =$D21*$C$7 -> 0 | M21: =$D21*$C$8 -> 0 | N21: =$D21*$C$9 -> 0 | Q21: =SUM(E21:P21) -> 50000
A22: =Parametrização!F7 -> 46143 | B22: ='DRE PREVISTO'!$K$9 -> 50000 | C22: 0 | D22: =+B22+C22 -> 50000 | I22: =$D22*$C$3 -> 15000 | J22: =$D22*$C$4 -> 20000 | K22: =$D22*$C$5 -> 15000 | L22: =$D22*$C$6 -> 0 | M22: =$D22*$C$7 -> 0 | N22: =$D22*$C$8 -> 0 | O22: =$D22*$C$9 -> 0 | Q22: =SUM(E22:P22) -> 50000
A23: =Parametrização!F8 -> 46174 | B23: ='DRE PREVISTO'!$M$9 -> 40000 | C23: 0 | D23: =+B23+C23 -> 40000 | J23: =$D23*$C$3 -> 12000 | K23: =$D23*$C$4 -> 16000 | L23: =$D23*$C$5 -> 12000 | M23: =$D23*$C$6 -> 0 | N23: =$D23*$C$7 -> 0 | O23: =$D23*$C$8 -> 0 | P23: =$D23*$C$9 -> 0 | Q23: =SUM(E23:P23) -> 40000
A24: =Parametrização!F9 -> 46204 | B24: ='DRE PREVISTO'!$O$9 -> 40000 | C24: 0 | D24: =+B24+C24 -> 40000 | K24: =$D24*$C$3 -> 12000 | L24: =$D24*$C$4 -> 16000 | M24: =$D24*$C$5 -> 12000 | N24: =$D24*$C$6 -> 0 | O24: =$D24*$C$7 -> 0 | P24: =$D24*$C$8 -> 0 | Q24: =SUM(E24:P24) -> 40000
A25: =Parametrização!F10 -> 46235 | B25: ='DRE PREVISTO'!$Q$9 -> 50000 | C25: 0 | D25: =+B25+C25 -> 50000 | L25: =$D25*$C$3 -> 15000 | M25: =$D25*$C$4 -> 20000 | N25: =$D25*$C$5 -> 15000 | O25: =$D25*$C$6 -> 0 | P25: =$D25*$C$7 -> 0 | Q25: =SUM(E25:P25) -> 50000
A26: =Parametrização!F11 -> 46266 | B26: ='DRE PREVISTO'!$S$9 -> 50000 | C26: 0 | D26: =+B26+C26 -> 50000 | M26: =$D26*$C$3 -> 15000 | N26: =$D26*$C$4 -> 20000 | O26: =$D26*$C$5 -> 15000 | P26: =$D26*$C$6 -> 0 | Q26: =SUM(E26:P26) -> 50000
A27: =Parametrização!F12 -> 46296 | B27: ='DRE PREVISTO'!$U$9 -> 50000 | C27: 0 | D27: =+B27+C27 -> 50000 | N27: =$D27*$C$3 -> 15000 | O27: =$D27*$C$4 -> 20000 | P27: =$D27*$C$5 -> 15000 | Q27: =SUM(E27:P27) -> 50000
A28: =Parametrização!F13 -> 46327 | B28: ='DRE PREVISTO'!$W$9 -> 50000 | C28: 0 | D28: =+B28+C28 -> 50000 | O28: =$D28*$C$3 -> 15000 | P28: =$D28*$C$4 -> 20000 | Q28: =SUM(E28:P28) -> 35000
A29: =Parametrização!F14 -> 46357 | B29: ='DRE PREVISTO'!$Y$9 -> 80000 | C29: 0 | D29: =+B29+C29 -> 80000 | P29: =$D29*$C$3 -> 24000 | Q29: =SUM(E29:P29) -> 24000
B30: =SUM(B18:B29) -> 595000 | E30: =SUM(E13:E29) -> 47000 | F30: =SUM(F13:F29) -> 44500 | G30: =SUM(G13:G29) -> 45000 | H30: =SUM(H13:H29) -> 48500 | I30: =SUM(I13:I29) -> 50000 | J30: =SUM(J13:J29) -> 47000 | K30: =SUM(K13:K29) -> 43000 | L30: =SUM(L13:L29) -> 43000 | ... Q30: =SUM(Q13:Q29) -> 574000

Sheet Analise do Preço de Compras
A1: ANÁLISE DE COMPRAS
A2: Taxa de Captação | E2: 0.02 | F2: a.m.
A3: CÓD. | B3: Descrição do Insumo | D3: Fornecedor | E3: Uunid. Medida | F3: Preço Bruto de Compra | G3: Prazo de Compra | H3: ICMS | I3: Prazo ICMS | J3: PIS | K3: Prazo PIS | L3: COFINS | M3: Prazo COFINS | N3: IPI | O3: Prazo IPI | P3: Frete | Q3: Prazo Frete | R3: Preço Líquido dos Materiais | S3: Markup | T3: Preço de Venda Sugerido | U3: Preço Praticado
A4: 1 | B4: xxxx | C4: =+A4 -> 1 | D4: ghghghg | E4: kg | F4: 20 | G4: 0 | H4: 0 | I4: 0 | J4: 0 | K4: 0 | L4: 0 | M4: 0 | N4: 0 | O4: 0 | P4: 0 | Q4: 0 | R4: =(F4*(1+$E$2)^(-G4/30)-((F4*N4)*(1+$E$2)^(-O4/30)))-((F4-(F4*N4))*H4)*(1+$E$2)^(-I4/30)-((F4-(F4*N4))*J4)*(1+$E$2)^(-K4/30)-((F4-(F4*N4))*L4)*(1+$E$2)^(-M4/30)+((F4-(F4*N4))*P4)*(1+$E$2)^(-Q4/30) -> 20 | S4: =Markup!$B$21 -> 2.5562372 | T4: =R4*S4 -> 51.124744 | U4: 4.5
A5: 2 | B5: gagagaga | C5: =+A5 -> 2 | D5: ghghghg | E5: m | F5: 21 | G5: 0 | H5: 0 | I5: 0 | J5: 0 | K5: 0 | L5: 0 | M5: 0 | N5: 0 | O5: 0 | P5: 0 | Q5: 0 | R5: =(F5*(1+$E$2)^(-G5/30)-((F5*N5)*(1+$E$2)^(-O5/30)))-((F5-(F5*N5))*H5)*(1+$E$2)^(-I5/30)-((F5-(F5*N5))*J5)*(1+$E$2)^(-K5/30)-((F5-(F5*N5))*L5)*(1+$E$2)^(-M5/30)+((F5-(F5*N5))*P5)*(1+$E$2)^(-Q5/30) -> 21 | S5: =Markup!$B$21 -> 2.5562372 | T5: =R5*S5 -> 53.680982 | U5: 0
A6: 3 | C6: =+A6 -> 3 | F6: 0 | G6: 0 | H6: 0 | I6: 0 | J6: 0 | K6: 0 | L6: 0 | M6: 0 | N6: 0 | O6: 0 | P6: 0 | Q6: 0 | R6: =(F6*(1+$E$2)^(-G6/30)-((F6*N6)*(1+$E$2)^(-O6/30)))-((F6-(F6*N6))*H6)*(1+$E$2)^(-I6/30)-((F6-(F6*N6))*J6)*(1+$E$2)^(-K6/30)-((F6-(F6*N6))*L6)*(1+$E$2)^(-M6/30)+((F6-(F6*N6))*P6)*(1+$E$2)^(-Q6/30) -> 0 | S6: =Markup!$B$21 -> 2.5562372 | T6: =R6*S6 -> 0
A7: 4 | C7: =+A7 -> 4 | F7: 0 | G7: 0 | H7: 0 | I7: 0 | J7: 0 | K7: 0 | L7: 0 | M7: 0 | N7: 0 | O7: 0 | P7: 0 | Q7: 0 | R7: =(F7*(1+$E$2)^(-G7/30)-((F7*N7)*(1+$E$2)^(-O7/30)))-((F7-(F7*N7))*H7)*(1+$E$2)^(-I7/30)-((F7-(F7*N7))*J7)*(1+$E$2)^(-K7/30)-((F7-(F7*N7))*L7)*(1+$E$2)^(-M7/30)+((F7-(F7*N7))*P7)*(1+$E$2)^(-Q7/30) -> 0 | S7: =Markup!$B$21 -> 2.5562372 | T7: =R7*S7 -> 0
A8: 5 | C8: =+A8 -> 5 | F8: 0 | G8: 0 | H8: 0.17 | I8: 0 | J8: 0 | K8: 0 | L8: 0 | M8: 0 | N8: 0 | O8: 0 | P8: 0 | Q8: 0 | R8: =(F8*(1+$E$2)^(-G8/30)-((F8*N8)*(1+$E$2)^(-O8/30)))-((F8-(F8*N8))*H8)*(1+$E$2)^(-I8/30)-((F8-(F8*N8))*J8)*(1+$E$2)^(-K8/30)-((F8-(F8*N8))*L8)*(1+$E$2)^(-M8/30)+((F8-(F8*N8))*P8)*(1+$E$2)^(-Q8/30) -> 0 | S8: =Markup!$B$21 -> 2.5562372 | T8: =R8*S8 -> 0
A9: 6 | C9: =+A9 -> 6 | F9: 0 | G9: 0 | H9: 0 | I9: 0 | J9: 0 | K9: 0 | L9: 0 | M9: 0 | N9: 0 | O9: 0 | P9: 0 | Q9: 0 | R9: =(F9*(1+$E$2)^(-G9/30)-((F9*N9)*(1+$E$2)^(-O9/30)))-((F9-(F9*N9))*H9)*(1+$E$2)^(-I9/30)-((F9-(F9*N9))*J9)*(1+$E$2)^(-K9/30)-((F9-(F9*N9))*L9)*(1+$E$2)^(-M9/30)+((F9-(F9*N9))*P9)*(1+$E$2)^(-Q9/30) -> 0 | S9: =Markup!$B$21 -> 2.5562372 | T9: =R9*S9 -> 0
A10: 7 | C10: =+A10 -> 7 | F10: 0 | G10: 0 | H10: 0 | I10: 0 | J10: 0 | K10: 0 | L10: 0 | M10: 0 | N10: 0 | O10: 0 | P10: 0 | Q10: 0 | R10: =(F10*(1+$E$2)^(-G10/30)-((F10*N10)*(1+$E$2)^(-O10/30)))-((F10-(F10*N10))*H10)*(1+$E$2)^(-I10/30)-((F10-(F10*N10))*J10)*(1+$E$2)^(-K10/30)-((F10-(F10*N10))*L10)*(1+$E$2)^(-M10/30)+((F10-(F10*N10))*P10)*(1+$E$2)^(-Q10/30) -> 0 | S10: =Markup!$B$21 -> 2.5562372 | T10: =R10*S10 -> 0
A11: 8 | C11: =+A11 -> 8 | F11: 0 | G11: 0 | H11: 0 | I11: 0 | J11: 0 | K11: 0 | L11: 0 | M11: 0 | N11: 0 | O11: 0 | P11: 0 | Q11: 0 | R11: =(F11*(1+$E$2)^(-G11/30)-((F11*N11)*(1+$E$2)^(-O11/30)))-((F11-(F11*N11))*H11)*(1+$E$2)^(-I11/30)-((F11-(F11*N11))*J11)*(1+$E$2)^(-K11/30)-((F11-(F11*N11))*L11)*(1+$E$2)^(-M11/30)+((F11-(F11*N11))*P11)*(1+$E$2)^(-Q11/30) -> 0 | S11: =Markup!$B$21 -> 2.5562372 | T11: =R11*S11 -> 0
A12: 9 | C12: =+A12 -> 9 | F12: 0 | G12: 0 | H12: 0 | I12: 0 | J12: 0 | K12: 0 | L12: 0 | M12: 0 | N12: 0 | O12: 0 | P12: 0 | Q12: 0 | R12: =(F12*(1+$E$2)^(-G12/30)-((F12*N12)*(1+$E$2)^(-O12/30)))-((F12-(F12*N12))*H12)*(1+$E$2)^(-I12/30)-((F12-(F12*N12))*J12)*(1+$E$2)^(-K12/30)-((F12-(F12*N12))*L12)*(1+$E$2)^(-M12/30)+((F12-(F12*N12))*P12)*(1+$E$2)^(-Q12/30) -> 0 | S12: =Markup!$B$21 -> 2.5562372 | T12: =R12*S12 -> 0
A13: 10 | C13: =+A13 -> 10 | F13: 0 | G13: 0 | H13: 0 | I13: 0 | J13: 0 | K13: 0 | L13: 0 | M13: 0 | N13: 0 | O13: 0 | P13: 0 | Q13: 0 | R13: =(F13*(1+$E$2)^(-G13/30)-((F13*N13)*(1+$E$2)^(-O13/30)))-((F13-(F13*N13))*H13)*(1+$E$2)^(-I13/30)-((F13-(F13*N13))*J13)*(1+$E$2)^(-K13/30)-((F13-(F13*N13))*L13)*(1+$E$2)^(-M13/30)+((F13-(F13*N13))*P13)*(1+$E$2)^(-Q13/30) -> 0 | S13: =Markup!$B$21 -> 2.5562372 | T13: =R13*S13 -> 0
A14: 11 | C14: =+A14 -> 11 | F14: 0 | G14: 0 | H14: 0 | I14: 0 | J14: 0 | K14: 0 | L14: 0 | M14: 0 | N14: 0 | O14: 0 | P14: 0 | Q14: 0 | R14: =(F14*(1+$E$2)^(-G14/30)-((F14*N14)*(1+$E$2)^(-O14/30)))-((F14-(F14*N14))*H14)*(1+$E$2)^(-I14/30)-((F14-(F14*N14))*J14)*(1+$E$2)^(-K14/30)-((F14-(F14*N14))*L14)*(1+$E$2)^(-M14/30)+((F14-(F14*N14))*P14)*(1+$E$2)^(-Q14/30) -> 0 | S14: =Markup!$B$21 -> 2.5562372 | T14: =R14*S14 -> 0
A15: 12 | C15: =+A15 -> 12 | F15: 0 | G15: 0 | H15: 0 | I15: 0 | J15: 0 | K15: 0 | L15: 0 | M15: 0 | N15: 0 | O15: 0 | P15: 0 | Q15: 0 | R15: =(F15*(1+$E$2)^(-G15/30)-((F15*N15)*(1+$E$2)^(-O15/30)))-((F15-(F15*N15))*H15)*(1+$E$2)^(-I15/30)-((F15-(F15*N15))*J15)*(1+$E$2)^(-K15/30)-((F15-(F15*N15))*L15)*(1+$E$2)^(-M15/30)+((F15-(F15*N15))*P15)*(1+$E$2)^(-Q15/30) -> 0 | S15: =Markup!$B$21 -> 2.5562372 | T15: =R15*S15 -> 0
A16: 13 | C16: =+A16 -> 13 | F16: 0 | G16: 0 | H16: 0 | I16: 0 | J16: 0 | K16: 0 | L16: 0 | M16: 0 | N16: 0 | O16: 0 | P16: 0 | Q16: 0 | R16: =(F16*(1+$E$2)^(-G16/30)-((F16*N16)*(1+$E$2)^(-O16/30)))-((F16-(F16*N16))*H16)*(1+$E$2)^(-I16/30)-((F16-(F16*N16))*J16)*(1+$E$2)^(-K16/30)-((F16-(F16*N16))*L16)*(1+$E$2)^(-M16/30)+((F16-(F16*N16))*P16)*(1+$E$2)^(-Q16/30) -> 0 | S16: =Markup!$B$21 -> 2.5562372 | T16: =R16*S16 -> 0
A17: 14 | C17: =+A17 -> 14 | F17: 0 | G17: 0 | H17: 0 | I17: 0 | J17: 0 | K17: 0 | L17: 0 | M17: 0 | N17: 0 | O17: 0 | P17: 0 | Q17: 0 | R17: =(F17*(1+$E$2)^(-G17/30)-((F17*N17)*(1+$E$2)^(-O17/30)))-((F17-(F17*N17))*H17)*(1+$E$2)^(-I17/30)-((F17-(F17*N17))*J17)*(1+$E$2)^(-K17/30)-((F17-(F17*N17))*L17)*(1+$E$2)^(-M17/30)+((F17-(F17*N17))*P17)*(1+$E$2)^(-Q17/30) -> 0 | S17: =Markup!$B$21 -> 2.5562372 | T17: =R17*S17 -> 0
A18: 15 | C18: =+A18 -> 15 | F18: 0 | G18: 0 | H18: 0 | I18: 0 | J18: 0 | K18: 0 | L18: 0 | M18: 0 | N18: 0 | O18: 0 | P18: 0 | Q18: 0 | R18: =(F18*(1+$E$2)^(-G18/30)-((F18*N18)*(1+$E$2)^(-O18/30)))-((F18-(F18*N18))*H18)*(1+$E$2)^(-I18/30)-((F18-(F18*N18))*J18)*(1+$E$2)^(-K18/30)-((F18-(F18*N18))*L18)*(1+$E$2)^(-M18/30)+((F18-(F18*N18))*P18)*(1+$E$2)^(-Q18/30) -> 0 | S18: =Markup!$B$21 -> 2.5562372 | T18: =R18*S18 -> 0
A19: 16 | F19: 0 | G19: 0 | H19: 0 | I19: 0 | J19: 0 | K19: 0 | L19: 0 | M19: 0 | N19: 0 | O19: 0 | P19: 0 | Q19: 0 | R19: =(F19*(1+$E$2)^(-G19/30)-((F19*N19)*(1+$E$2)^(-O19/30)))-((F19-(F19*N19))*H19)*(1+$E$2)^(-I19/30)-((F19-(F19*N19))*J19)*(1+$E$2)^(-K19/30)-((F19-(F19*N19))*L19)*(1+$E$2)^(-M19/30)+((F19-(F19*N19))*P19)*(1+$E$2)^(-Q19/30) -> 0 | S19: =Markup!$B$21 -> 2.5562372 | T19: =R19*S19 -> 0
A20: 17 | F20: 0 | G20: 0 | H20: 0 | I20: 0 | J20: 0 | K20: 0 | L20: 0 | M20: 0 | N20: 0 | O20: 0 | P20: 0 | Q20: 0 | R20: =(F20*(1+$E$2)^(-G20/30)-((F20*N20)*(1+$E$2)^(-O20/30)))-((F20-(F20*N20))*H20)*(1+$E$2)^(-I20/30)-((F20-(F20*N20))*J20)*(1+$E$2)^(-K20/30)-((F20-(F20*N20))*L20)*(1+$E$2)^(-M20/30)+((F20-(F20*N20))*P20)*(1+$E$2)^(-Q20/30) -> 0 | S20: =Markup!$B$21 -> 2.5562372 | T20: =R20*S20 -> 0
A21: 18 | F21: 0 | G21: 0 | H21: 0 | I21: 0 | J21: 0 | K21: 0 | L21: 0 | M21: 0 | N21: 0 | O21: 0 | P21: 0 | Q21: 0 | R21: =(F21*(1+$E$2)^(-G21/30)-((F21*N21)*(1+$E$2)^(-O21/30)))-((F21-(F21*N21))*H21)*(1+$E$2)^(-I21/30)-((F21-(F21*N21))*J21)*(1+$E$2)^(-K21/30)-((F21-(F21*N21))*L21)*(1+$E$2)^(-M21/30)+((F21-(F21*N21))*P21)*(1+$E$2)^(-Q21/30) -> 0 | S21: =Markup!$B$21 -> 2.5562372 | T21: =R21*S21 -> 0
A22: 19 | F22: 0 | G22: 0 | H22: 0 | I22: 0 | J22: 0 | K22: 0 | L22: 0 | M22: 0 | N22: 0 | O22: 0 | P22: 0 | Q22: 0 | R22: =(F22*(1+$E$2)^(-G22/30)-((F22*N22)*(1+$E$2)^(-O22/30)))-((F22-(F22*N22))*H22)*(1+$E$2)^(-I22/30)-((F22-(F22*N22))*J22)*(1+$E$2)^(-K22/30)-((F22-(F22*N22))*L22)*(1+$E$2)^(-M22/30)+((F22-(F22*N22))*P22)*(1+$E$2)^(-Q22/30) -> 0 | S22: =Markup!$B$21 -> 2.5562372 | T22: =R22*S22 -> 0
A23: 20 | F23: 0 | G23: 0 | H23: 0 | I23: 0 | J23: 0 | K23: 0 | L23: 0 | M23: 0 | N23: 0 | O23: 0 | P23: 0 | Q23: 0 | R23: =(F23*(1+$E$2)^(-G23/30)-((F23*N23)*(1+$E$2)^(-O23/30)))-((F23-(F23*N23))*H23)*(1+$E$2)^(-I23/30)-((F23-(F23*N23))*J23)*(1+$E$2)^(-K23/30)-((F23-(F23*N23))*L23)*(1+$E$2)^(-M23/30)+((F23-(F23*N23))*P23)*(1+$E$2)^(-Q23/30) -> 0 | S23: =Markup!$B$21 -> 2.5562372 | T23: =R23*S23 -> 0

Sheet Ficha Técnica
A1: Referência do Produto | C1: 1 | F1: Data
A2: Descrição do Produto
A3: Cód. | B3: Descrição | C3: Consumo | D3: Unid. Med. | E3: Preço Unit | F3: Custo
A4: Materiais
A5: =VLOOKUP(B5,'Analise do Preço de Compras'!$B$4:$C$23,2,0) -> 1 | B5: xxxx | C5: 0 | D5: =VLOOKUP($A5,'Analise do Preço de Compras'!$A$4:$R$43,5,FALSE) -> kg | E5: =VLOOKUP($A5,'Analise do Preço de Compras'!$A$4:$R$43,18,FALSE) -> 20 | F5: =IFERROR(C5*E5,0) -> 0
A6: =VLOOKUP(B6,'Analise do Preço de Compras'!$B$4:$C$23,2,0) -> 2 | B6: gagagaga | C6: 0 | D6: =VLOOKUP($A6,'Analise do Preço de Compras'!$A$4:$R$43,5,FALSE) -> m | E6: =VLOOKUP($A6,'Analise do Preço de Compras'!$A$4:$R$43,18,FALSE) -> 21 | F6: =IFERROR(C6*E6,0) -> 0
A7: =VLOOKUP(B7,'Analise do Preço de Compras'!$B$4:$C$23,2,0) -> #N/A | C7: 0 | D7: =VLOOKUP($A7,'Analise do Preço de Compras'!$A$4:$R$43,5,FALSE) -> #N/A | E7: =VLOOKUP($A7,'Analise do Preço de Compras'!$A$4:$R$43,18,FALSE) -> #N/A | F7: =IFERROR(C7*E7,0) -> 0
A8: =VLOOKUP(B8,'Analise do Preço de Compras'!$B$4:$C$23,2,0) -> #N/A | C8: 0 | D8: =VLOOKUP($A8,'Analise do Preço de Compras'!$A$4:$R$43,5,FALSE) -> #N/A | E8: =VLOOKUP($A8,'Analise do Preço de Compras'!$A$4:$R$43,18,FALSE) -> #N/A | F8: =IFERROR(C8*E8,0) -> 0
A9: =VLOOKUP(B9,'Analise do Preço de Compras'!$B$4:$C$23,2,0) -> #N/A | C9: 0 | D9: =VLOOKUP($A9,'Analise do Preço de Compras'!$A$4:$R$43,5,FALSE) -> #N/A | E9: =VLOOKUP($A9,'Analise do Preço de Compras'!$A$4:$R$43,18,FALSE) -> #N/A | F9: =IFERROR(C9*E9,0) -> 0
A10: =VLOOKUP(B10,'Analise do Preço de Compras'!$B$4:$C$23,2,0) -> #N/A | C10: 0 | D10: =VLOOKUP($A10,'Analise do Preço de Compras'!$A$4:$R$43,5,FALSE) -> #N/A | E10: =VLOOKUP($A10,'Analise do Preço de Compras'!$A$4:$R$43,18,FALSE) -> #N/A | F10: =IFERROR(C10*E10,0) -> 0
A11: =VLOOKUP(B11,'Analise do Preço de Compras'!$B$4:$C$23,2,0) -> #N/A | C11: 0 | D11: =VLOOKUP($A11,'Analise do Preço de Compras'!$A$4:$R$43,5,FALSE) -> #N/A | E11: =VLOOKUP($A11,'Analise do Preço de Compras'!$A$4:$R$43,18,FALSE) -> #N/A | F11: =IFERROR(C11*E11,0) -> 0
A12: =VLOOKUP(B12,'Analise do Preço de Compras'!$B$4:$C$23,2,0) -> #N/A | C12: 0 | D12: =VLOOKUP($A12,'Analise do Preço de Compras'!$A$4:$R$43,5,FALSE) -> #N/A | E12: =VLOOKUP($A12,'Analise do Preço de Compras'!$A$4:$R$43,18,FALSE) -> #N/A | F12: =IFERROR(C12*E12,0) -> 0
A13: =VLOOKUP(B13,'Analise do Preço de Compras'!$B$4:$C$23,2,0) -> #N/A | C13: 0 | D13: =VLOOKUP($A13,'Analise do Preço de Compras'!$A$4:$R$43,5,FALSE) -> #N/A | E13: =VLOOKUP($A13,'Analise do Preço de Compras'!$A$4:$R$43,18,FALSE) -> #N/A | F13: =IFERROR(C13*E13,0) -> 0
A14: =VLOOKUP(B14,'Analise do Preço de Compras'!$B$4:$C$23,2,0) -> #N/A | C14: 0 | D14: =VLOOKUP($A14,'Analise do Preço de Compras'!$A$4:$R$43,5,FALSE) -> #N/A | E14: =VLOOKUP($A14,'Analise do Preço de Compras'!$A$4:$R$43,18,FALSE) -> #N/A | F14: =IFERROR(C14*E14,0) -> 0
A15: =VLOOKUP(B15,'Analise do Preço de Compras'!$B$4:$C$23,2,0) -> #N/A | C15: 0 | D15: =VLOOKUP($A15,'Analise do Preço de Compras'!$A$4:$R$43,5,FALSE) -> #N/A | E15: =VLOOKUP($A15,'Analise do Preço de Compras'!$A$4:$R$43,18,FALSE) -> #N/A | F15: =IFERROR(C15*E15,0) -> 0
A16: =VLOOKUP(B16,'Analise do Preço de Compras'!$B$4:$C$23,2,0) -> #N/A | C16: 0 | D16: =VLOOKUP($A16,'Analise do Preço de Compras'!$A$4:$R$43,5,FALSE) -> #N/A | E16: =VLOOKUP($A16,'Analise do Preço de Compras'!$A$4:$R$43,18,FALSE) -> #N/A | F16: =IFERROR(C16*E16,0) -> 0
A17: Sub-total | F17: =SUM(F5:F14) -> 0
A18: Mão de Obra
A19: 120 | B19: ='[2]Custo MOD CIF'!$B$4 -> 0 | D19: min | E19: =VLOOKUP($A19,'Analise do Preço de Compras'!$A$4:$R$43,18,FALSE) -> #N/A | F19: =IFERROR(C19*E19,0) -> 0
A20: 121 | B20: ='[2]Custo MOD CIF'!$C$4 -> 0 | D20: min | E20: =VLOOKUP($A20,'Analise do Preço de Compras'!$A$4:$R$43,18,FALSE) -> #N/A | F20: =IFERROR(C20*E20,0) -> 0
A21: 122 | B21: ='[2]Custo MOD CIF'!$D$4 -> 0 | D21: min | E21: =VLOOKUP($A21,'Analise do Preço de Compras'!$A$4:$R$43,18,FALSE) -> #N/A | F21: =IFERROR(C21*E21,0) -> 0
A22: 123 | B22: ='[2]Custo MOD CIF'!$E$4 -> 0 | D22: min | E22: =VLOOKUP($A22,'Analise do Preço de Compras'!$A$4:$R$43,18,FALSE) -> #N/A | F22: =IFERROR(C22*E22,0) -> 0
A23: 124 | B23: ='[2]Custo MOD CIF'!$F$4 -> 0 | D23: min | E23: =VLOOKUP($A23,'Analise do Preço de Compras'!$A$4:$R$43,18,FALSE) -> #N/A | F23: =IFERROR(C23*E23,0) -> 0
A24: Sub-total | F24: =SUM(F19:F23) -> 0
A25: Custos Indiretos de Fabricação
A26: ='[2]Custo MOD CIF'!$B$3 -> 120 | B26: ='[2]Custo MOD CIF'!$B$4 -> 0 | D26: min | E26: =VLOOKUP($A26,'Analise do Preço de Compras'!$A$4:$R$43,18,FALSE) -> #N/A | F26: =IFERROR(C26*E26,0) -> 0
A27: ='[2]Custo MOD CIF'!$C$3 -> 121 | B27: ='[2]Custo MOD CIF'!$C$4 -> 0 | D27: min | E27: =VLOOKUP($A27,'Analise do Preço de Compras'!$A$4:$R$43,18,FALSE) -> #N/A | F27: =IFERROR(C27*E27,0) -> 0
A28: ='[2]Custo MOD CIF'!$D$3 -> 122 | B28: ='[2]Custo MOD CIF'!$D$4 -> 0 | D28: min | E28: =VLOOKUP($A28,'Analise do Preço de Compras'!$A$4:$R$43,18,FALSE) -> #N/A | F28: =IFERROR(C28*E28,0) -> 0
A29: ='[2]Custo MOD CIF'!$E$3 -> 123 | B29: ='[2]Custo MOD CIF'!$E$4 -> 0 | D29: min | E29: =VLOOKUP($A29,'Analise do Preço de Compras'!$A$4:$R$43,18,FALSE) -> #N/A | F29: =IFERROR(C29*E29,0) -> 0
A30: ='[2]Custo MOD CIF'!$F$3 -> 124 | B30: ='[2]Custo MOD CIF'!$F$4 -> 0 | D30: min | E30: =VLOOKUP($A30,'Analise do Preço de Compras'!$A$4:$R$43,18,FALSE) -> #N/A | F30: =IFERROR(C30*E30,0) -> 0
A31: Sub-total | F31: =SUM(F26:F30) -> 0
B32: Custo Total do Produto | F32: =F17+F24+F31 -> 0
B33: Mark-up | F33: =Markup!B21 -> 2.5562372
B34: Preço de Venda | F34: =F32*F33 -> 0

Sheet Fluxo de Caixa Mensal
B1: FLUXO DE CAIXA MENSAL (R$) | Z1: Exercício | AA1: 2024
B2: ='DRE PREVISTO'!C4 -> #REF! | C2: ='DRE PREVISTO'!D4 -> #REF! | D2: ='DRE PREVISTO'!E4 -> #REF! | E2: ='DRE PREVISTO'!F4 -> #REF! | F2: ='DRE PREVISTO'!G4 -> #REF! | G2: ='DRE PREVISTO'!H4 -> #REF! | H2: ='DRE PREVISTO'!I4 -> #REF! | I2: ='DRE PREVISTO'!J4 -> #REF! | ... Y2: ='DRE PREVISTO'!Z4 -> #REF!
B3: ='DRE PREVISTO'!C5 -> #REF! | C3: ='DRE PREVISTO'!D5 -> #REF! | D3: ='DRE PREVISTO'!E5 -> #REF! | E3: ='DRE PREVISTO'!F5 -> #REF! | F3: ='DRE PREVISTO'!G5 -> #REF! | G3: ='DRE PREVISTO'!H5 -> #REF! | H3: ='DRE PREVISTO'!I5 -> #REF! | I3: ='DRE PREVISTO'!J5 -> #REF! | ... Y3: ='DRE PREVISTO'!Z5 -> #REF!
B4: 1 | D4: =MONTH(D3) -> #REF! | F4: =MONTH(F3) -> #REF! | H4: =MONTH(H3) -> #REF! | J4: =MONTH(J3) -> #REF! | L4: =MONTH(L3) -> #REF! | N4: =MONTH(N3) -> #REF! | P4: =MONTH(P3) -> #REF! | R4: =MONTH(R3) -> #REF! | T4: =MONTH(T3) -> #REF! | V4: =MONTH(V3) -> #REF! | X4: =MONTH(X3) -> #REF!
A5: Fluxo de Caixa | B5: ='DRE PREVISTO'!C3 -> 46023 | D5: ='DRE PREVISTO'!E3 -> 46054 | F5: ='DRE PREVISTO'!G3 -> 46082 | H5: ='DRE PREVISTO'!I3 -> 46113 | J5: ='DRE PREVISTO'!K3 -> 46143 | L5: ='DRE PREVISTO'!M3 -> 46174 | N5: ='DRE PREVISTO'!O3 -> 46204 | P5: ='DRE PREVISTO'!Q3 -> 46235 | R5: ='DRE PREVISTO'!S3 -> 46266 | T5: ='DRE PREVISTO'!U3 -> 46296 | V5: ='DRE PREVISTO'!W3 -> 46327 | X5: ='DRE PREVISTO'!Y3 -> 46357 | Z5: ANO
B6: P | C6: R | D6: P | E6: R | F6: P | G6: R | H6: P | I6: R | J6: P | K6: R | L6: P | M6: R | N6: P | O6: R | P6: P | Q6: R | R6: P | S6: R | T6: P | U6: R | V6: P | W6: R | X6: P | Y6: R | Z6: P | AA6: R
A7: SALDO INICIAL | B7: 5000 | C7: 0 | D7: =B40 -> 8513.3487 | E7: =C40 -> 0 | F7: =D40 -> 8768.168 | G7: =E40 -> 0 | H7: =F40 -> 3764.4579 | I7: =G40 -> 0 | J7: =H40 -> 2260.7478 | K7: =I40 -> 0 | ... Y7: =W40 -> 0 | Z7: =B7 -> 5000 | AA7: =C7 -> 0
A8: OPERACIONAL
A9: ENTRADAS | B9: =SUM(B10:B11) -> 48000 | C9: =SUM(C10:C11) -> 0 | D9: =SUM(D10:D11) -> 47500 | E9: =SUM(E10:E11) -> 0 | F9: =SUM(F10:F11) -> 45000 | G9: =SUM(G10:G11) -> 0 | H9: =SUM(H10:H11) -> 48500 | I9: =SUM(I10:I11) -> 0 | ... AA9: =SUM(AA10:AA11) -> 0
A10: Recebimentos No Vencimento | B10: 48000 | C10: 0 | D10: 47500 | E10: 0 | F10: ='Distribuição do Recebimento'!G30 -> 45000 | G10: 0 | H10: ='Distribuição do Recebimento'!H30 -> 48500 | I10: 0 | J10: ='Distribuição do Recebimento'!I30 -> 50000 | K10: 0 | L10: ='Distribuição do Recebimento'!J30 -> 47000 | M10: 0 | N10: ='Distribuição do Recebimento'!K30 -> 43000 | O10: 0 | P10: ='Distribuição do Recebimento'!L30 -> 43000 | Q10: 0 | R10: ='Distribuição do Recebimento'!M30 -> 47000 | S10: 0 | T10: ='Distribuição do Recebimento'!N30 -> 50000 | U10: 0 | V10: ='Distribuição do Recebimento'!O30 -> 50000 | W10: 0 | X10: ='Distribuição do Recebimento'!P30 -> 59000 | Y10: 0 | Z10: =B10+D10+F10+H10+J10+L10+N10+P10+R10+T10+V10+X10 -> 578000 | AA10: =C10+E10+G10+I10+K10+M10+O10+Q10+S10+U10+W10+Y10 -> 0
Z11: =B11+D11+F11+H11+J11+L11+N11+P11+R11+T11+V11+X11 -> 0 | AA11: =C11+E11+G11+I11+K11+M11+O11+Q11+S11+U11+W11+Y11 -> 0
A12: PAGAMENTOS OPERACIONAIS | B12: =SUM(B13:B21) -> 44486.651 | C12: =SUM(C13:C21) -> 0 | D12: =SUM(D13:D21) -> 47245.181 | E12: =SUM(E13:E21) -> 0 | F12: =SUM(F13:F21) -> 50003.71 | G12: =SUM(G13:G21) -> 0 | H12: =SUM(H13:H21) -> 50003.71 | I12: =SUM(I13:I21) -> 0 | ... AA12: =SUM(AA13:AA21) -> 0
A13: FORNECEDORES DE MATERIAIS (PROD) | B13: ='DRE PREVISTO'!C18 -> 16000 | C13: 0 | D13: ='DRE PREVISTO'!E18 -> 18000 | E13: 0 | F13: ='DRE PREVISTO'!G18 -> 20000 | G13: 0 | H13: ='DRE PREVISTO'!I18 -> 20000 | I13: 0 | J13: ='DRE PREVISTO'!K18 -> 20000 | K13: 0 | L13: ='DRE PREVISTO'!M18 -> 16000 | M13: 0 | N13: ='DRE PREVISTO'!O18 -> 16000 | O13: 0 | P13: ='DRE PREVISTO'!Q18 -> 20000 | Q13: 0 | R13: ='DRE PREVISTO'!S18 -> 20000 | S13: 0 | T13: ='DRE PREVISTO'!U18 -> 20000 | U13: 0 | V13: ='DRE PREVISTO'!W18 -> 20000 | W13: 0 | X13: ='DRE PREVISTO'!Y18 -> 32000 | Y13: 0 | Z13: =B13+D13+F13+H13+J13+L13+N13+P13+R13+T13+V13+X13 -> 238000 | AA13: =C13+E13+G13+I13+K13+M13+O13+Q13+S13+U13+W13+Y13 -> 0
A14: CUSTOS INDIRETOS DE FABRICAÇÃO (CIF) | B14: ='DRE PREVISTO'!C21-'DRE PREVISTO'!C22-'DRE PREVISTO'!C23 -> 0 | C14: 0 | D14: ='DRE PREVISTO'!E21-'DRE PREVISTO'!E22-'DRE PREVISTO'!E23 -> 0 | E14: 0 | F14: ='DRE PREVISTO'!G21-'DRE PREVISTO'!G22-'DRE PREVISTO'!G23 -> 0 | G14: 0 | H14: ='DRE PREVISTO'!I21-'DRE PREVISTO'!I22-'DRE PREVISTO'!I23 -> 0 | I14: 0 | J14: ='DRE PREVISTO'!K21-'DRE PREVISTO'!K22-'DRE PREVISTO'!K23 -> 0 | K14: 0 | L14: ='DRE PREVISTO'!M21-'DRE PREVISTO'!M22-'DRE PREVISTO'!M23 -> 0 | M14: 0 | N14: ='DRE PREVISTO'!O21-'DRE PREVISTO'!O22-'DRE PREVISTO'!O23 -> 0 | O14: 0 | P14: ='DRE PREVISTO'!Q21-'DRE PREVISTO'!Q22-'DRE PREVISTO'!Q23 -> 0 | Q14: 0 | R14: ='DRE PREVISTO'!S21-'DRE PREVISTO'!S22-'DRE PREVISTO'!S23 -> 0 | S14: 0 | T14: ='DRE PREVISTO'!U21-'DRE PREVISTO'!U22-'DRE PREVISTO'!U23 -> 0 | U14: 0 | V14: ='DRE PREVISTO'!W21-'DRE PREVISTO'!W22-'DRE PREVISTO'!W23 -> 0 | W14: 0 | X14: ='DRE PREVISTO'!Y21-'DRE PREVISTO'!Y22-'DRE PREVISTO'!Y23 -> 0 | Y14: 0 | Z14: =B14+D14+F14+H14+J14+L14+N14+P14+R14+T14+V14+X14 -> 0 | AA14: =C14+E14+G14+I14+K14+M14+O14+Q14+S14+U14+W14+Y14 -> 0
A15: FOLHA DE PAGAMENTO | B15: ='DRE PREVISTO'!C19+'DRE PREVISTO'!C22+'DRE PREVISTO'!C37+'DRE PREVISTO'!C38+'DRE PREVISTO'!C39+'DRE PREVISTO'!C40 -> 14280 | C15: 0 | D15: ='DRE PREVISTO'!E19+'DRE PREVISTO'!E22+'DRE PREVISTO'!E37+'DRE PREVISTO'!E38+'DRE PREVISTO'!E39+'DRE PREVISTO'!E40 -> 14280 | E15: 0 | F15: ='DRE PREVISTO'!G19+'DRE PREVISTO'!G22+'DRE PREVISTO'!G37+'DRE PREVISTO'!G38+'DRE PREVISTO'!G39+'DRE PREVISTO'!G40 -> 14280 | G15: 0 | H15: ='DRE PREVISTO'!I19+'DRE PREVISTO'!I22+'DRE PREVISTO'!I37+'DRE PREVISTO'!I38+'DRE PREVISTO'!I39+'DRE PREVISTO'!I40 -> 14280 | I15: 0 | J15: ='DRE PREVISTO'!K19+'DRE PREVISTO'!K22+'DRE PREVISTO'!K37+'DRE PREVISTO'!K38+'DRE PREVISTO'!K39+'DRE PREVISTO'!K40 -> 14280 | K15: 0 | L15: ='DRE PREVISTO'!M19+'DRE PREVISTO'!M22+'DRE PREVISTO'!M37+'DRE PREVISTO'!M38+'DRE PREVISTO'!M39+'DRE PREVISTO'!M40 -> 14280 | M15: 0 | N15: ='DRE PREVISTO'!O19+'DRE PREVISTO'!O22+'DRE PREVISTO'!O37+'DRE PREVISTO'!O38+'DRE PREVISTO'!O39+'DRE PREVISTO'!O40 -> 14280 | O15: 0 | P15: ='DRE PREVISTO'!Q19+'DRE PREVISTO'!Q22+'DRE PREVISTO'!Q37+'DRE PREVISTO'!Q38+'DRE PREVISTO'!Q39+'DRE PREVISTO'!Q40 -> 14280 | Q15: 0 | R15: ='DRE PREVISTO'!S19+'DRE PREVISTO'!S22+'DRE PREVISTO'!S37+'DRE PREVISTO'!S38+'DRE PREVISTO'!S39+'DRE PREVISTO'!S40 -> 14280 | S15: 0 | T15: ='DRE PREVISTO'!U19+'DRE PREVISTO'!U22+'DRE PREVISTO'!U37+'DRE PREVISTO'!U38+'DRE PREVISTO'!U39+'DRE PREVISTO'!U40 -> 14280 | U15: 0 | V15: ='DRE PREVISTO'!W19+'DRE PREVISTO'!W22+'DRE PREVISTO'!W37+'DRE PREVISTO'!W38+'DRE PREVISTO'!W39+'DRE PREVISTO'!W40 -> 14280 | W15: 0 | X15: ='DRE PREVISTO'!Y19+'DRE PREVISTO'!Y22+'DRE PREVISTO'!Y37+'DRE PREVISTO'!Y38+'DRE PREVISTO'!Y39+'DRE PREVISTO'!Y40 -> 14280 | Y15: 0 | Z15: =B15+D15+F15+H15+J15+L15+N15+P15+R15+T15+V15+X15 -> 171360 | AA15: =C15+E15+G15+I15+K15+M15+O15+Q15+S15+U15+W15+Y15 -> 0
A16: IMPOSTOS A PAGAR | B16: ='DRE PREVISTO'!C10 -> 2868.2353 | C16: 0 | D16: ='DRE PREVISTO'!E10 -> 3226.7647 | E16: 0 | F16: ='DRE PREVISTO'!G10 -> 3585.2941 | G16: 0 | H16: ='DRE PREVISTO'!I10 -> 3585.2941 | I16: 0 | J16: ='DRE PREVISTO'!K10 -> 3585.2941 | K16: 0 | L16: ='DRE PREVISTO'!M10 -> 2868.2353 | M16: 0 | N16: ='DRE PREVISTO'!O10 -> 2868.2353 | O16: 0 | P16: ='DRE PREVISTO'!Q10 -> 3585.2941 | Q16: 0 | R16: ='DRE PREVISTO'!S10 -> 3585.2941 | S16: 0 | T16: ='DRE PREVISTO'!U10 -> 3585.2941 | U16: 0 | V16: ='DRE PREVISTO'!W10 -> 3585.2941 | W16: 0 | X16: ='DRE PREVISTO'!Y10 -> 5736.4706 | Y16: 0 | Z16: =B16+D16+F16+H16+J16+L16+N16+P16+R16+T16+V16+X16 -> 42665 | AA16: =C16+E16+G16+I16+K16+M16+O16+Q16+S16+U16+W16+Y16 -> 0
A17: DESPESAS COMERCIAIS VARIÁVEIS | B17: ='DRE PREVISTO'!C31 -> 3200 | C17: 0 | D17: ='DRE PREVISTO'!E31 -> 3600 | E17: 0 | F17: ='DRE PREVISTO'!G31 -> 4000 | G17: 0 | H17: ='DRE PREVISTO'!I31 -> 4000 | I17: 0 | J17: ='DRE PREVISTO'!K31 -> 4000 | K17: 0 | L17: ='DRE PREVISTO'!M31 -> 3200 | M17: 0 | N17: ='DRE PREVISTO'!O31 -> 3200 | O17: 0 | P17: ='DRE PREVISTO'!Q31 -> 4000 | Q17: 0 | R17: ='DRE PREVISTO'!S31 -> 4000 | S17: 0 | T17: ='DRE PREVISTO'!U31 -> 4000 | U17: 0 | V17: ='DRE PREVISTO'!W31 -> 4000 | W17: 0 | X17: ='DRE PREVISTO'!Y31 -> 6400 | Y17: 0 | Z17: =B17+D17+F17+H17+J17+L17+N17+P17+R17+T17+V17+X17 -> 47600 | AA17: =C17+E17+G17+I17+K17+M17+O17+Q17+S17+U17+W17+Y17 -> 0
A18: ENCARGOS A PAGAR (INSS) | C18: 0 | E18: 0 | G18: 0 | I18: 0 | K18: 0 | M18: 0 | O18: 0 | Q18: 0 | S18: 0 | U18: 0 | W18: 0 | Y18: 0 | Z18: =B18+D18+F18+H18+J18+L18+N18+P18+R18+T18+V18+X18 -> 0 | AA18: =C18+E18+G18+I18+K18+M18+O18+Q18+S18+U18+W18+Y18 -> 0
A19: ENCARGOS A PAGAR | B19: ='DRE PREVISTO'!C20+'DRE PREVISTO'!C23+'DRE PREVISTO'!C42 -> 2688.416 | C19: 0 | D19: ='DRE PREVISTO'!E20+'DRE PREVISTO'!E23+'DRE PREVISTO'!E42 -> 2688.416 | E19: 0 | F19: ='DRE PREVISTO'!G20+'DRE PREVISTO'!G23+'DRE PREVISTO'!G42 -> 2688.416 | G19: 0 | H19: ='DRE PREVISTO'!I20+'DRE PREVISTO'!I23+'DRE PREVISTO'!I42 -> 2688.416 | I19: 0 | J19: ='DRE PREVISTO'!K20+'DRE PREVISTO'!K23+'DRE PREVISTO'!K42 -> 2688.416 | K19: 0 | L19: ='DRE PREVISTO'!M20+'DRE PREVISTO'!M23+'DRE PREVISTO'!M42 -> 2688.416 | M19: 0 | N19: ='DRE PREVISTO'!O20+'DRE PREVISTO'!O23+'DRE PREVISTO'!O42 -> 2688.416 | O19: 0 | P19: ='DRE PREVISTO'!Q20+'DRE PREVISTO'!Q23+'DRE PREVISTO'!Q42 -> 2688.416 | Q19: 0 | R19: ='DRE PREVISTO'!S20+'DRE PREVISTO'!S23+'DRE PREVISTO'!S42 -> 2688.416 | S19: 0 | T19: ='DRE PREVISTO'!U20+'DRE PREVISTO'!U23+'DRE PREVISTO'!U42 -> 2688.416 | U19: 0 | V19: ='DRE PREVISTO'!W20+'DRE PREVISTO'!W23+'DRE PREVISTO'!W42 -> 2688.416 | W19: 0 | X19: ='DRE PREVISTO'!Y20+'DRE PREVISTO'!Y23+'DRE PREVISTO'!Y42 -> 2688.416 | Y19: 0 | Z19: =B19+D19+F19+H19+J19+L19+N19+P19+R19+T19+V19+X19 -> 32260.992 | AA19: =C19+E19+G19+I19+K19+M19+O19+Q19+S19+U19+W19+Y19 -> 0
A20: DESPESAS COMERCIAIS | C20: 0 | E20: 0 | G20: 0 | I20: 0 | K20: 0 | M20: 0 | O20: 0 | Q20: 0 | S20: 0 | U20: 0 | W20: 0 | Y20: 0
A21: DESPESAS ADMINISTRATIVAS | B21: ='DRE PREVISTO'!C36-'DRE PREVISTO'!C37-'DRE PREVISTO'!C38-'DRE PREVISTO'!C39-'DRE PREVISTO'!C40-'DRE PREVISTO'!C42 -> 5450 | C21: 0 | D21: ='DRE PREVISTO'!E36-'DRE PREVISTO'!E37-'DRE PREVISTO'!E38-'DRE PREVISTO'!E39-'DRE PREVISTO'!E40-'DRE PREVISTO'!E42 -> 5450 | E21: 0 | F21: ='DRE PREVISTO'!G36-'DRE PREVISTO'!G37-'DRE PREVISTO'!G38-'DRE PREVISTO'!G39-'DRE PREVISTO'!G40-'DRE PREVISTO'!G42 -> 5450 | G21: 0 | H21: ='DRE PREVISTO'!I36-'DRE PREVISTO'!I37-'DRE PREVISTO'!I38-'DRE PREVISTO'!I39-'DRE PREVISTO'!I40-'DRE PREVISTO'!I42 -> 5450 | I21: 0 | J21: ='DRE PREVISTO'!K36-'DRE PREVISTO'!K37-'DRE PREVISTO'!K38-'DRE PREVISTO'!K39-'DRE PREVISTO'!K40-'DRE PREVISTO'!K42 -> 5450 | K21: 0 | L21: ='DRE PREVISTO'!M36-'DRE PREVISTO'!M37-'DRE PREVISTO'!M38-'DRE PREVISTO'!M39-'DRE PREVISTO'!M40-'DRE PREVISTO'!M42 -> 5450 | M21: 0 | N21: ='DRE PREVISTO'!O36-'DRE PREVISTO'!O37-'DRE PREVISTO'!O38-'DRE PREVISTO'!O39-'DRE PREVISTO'!O40-'DRE PREVISTO'!O42 -> 5450 | O21: 0 | P21: ='DRE PREVISTO'!Q36-'DRE PREVISTO'!Q37-'DRE PREVISTO'!Q38-'DRE PREVISTO'!Q39-'DRE PREVISTO'!Q40-'DRE PREVISTO'!Q42 -> 5450 | Q21: 0 | R21: ='DRE PREVISTO'!S36-'DRE PREVISTO'!S37-'DRE PREVISTO'!S38-'DRE PREVISTO'!S39-'DRE PREVISTO'!S40-'DRE PREVISTO'!S42 -> 5450 | S21: 0 | T21: ='DRE PREVISTO'!U36-'DRE PREVISTO'!U37-'DRE PREVISTO'!U38-'DRE PREVISTO'!U39-'DRE PREVISTO'!U40-'DRE PREVISTO'!U42 -> 5450 | U21: 0 | V21: ='DRE PREVISTO'!W36-'DRE PREVISTO'!W37-'DRE PREVISTO'!W38-'DRE PREVISTO'!W39-'DRE PREVISTO'!W40-'DRE PREVISTO'!W42 -> 5450 | W21: 0 | X21: ='DRE PREVISTO'!Y36-'DRE PREVISTO'!Y37-'DRE PREVISTO'!Y38-'DRE PREVISTO'!Y39-'DRE PREVISTO'!Y40-'DRE PREVISTO'!Y42 -> 5450 | Y21: 0 | Z21: =B21+D21+F21+H21+J21+L21+N21+P21+R21+T21+V21+X21 -> 65400 | AA21: =C21+E21+G21+I21+K21+M21+O21+Q21+S21+U21+W21+Y21 -> 0
A22: FLUXO DE CAIXA OPERACIONAL | B22: =B9-B12 -> 3513.3487 | C22: =C9-C12 -> 0 | D22: =D9-D12 -> 254.81929 | E22: =E9-E12 -> 0 | F22: =F9-F12 -> -5003.7101 | G22: =G9-G12 -> 0 | H22: =H9-H12 -> -1503.7101 | I22: =I9-I12 -> 0 | ... AA22: =AA9-AA12 -> 0
A23: INVESTIMENTOS | B23: =SUM(B24:B29) -> 0 | C23: =SUM(C24:C29) -> 0 | D23: =SUM(D24:D29) -> 0 | E23: =SUM(E24:E29) -> 0 | F23: =SUM(F24:F29) -> 0 | G23: =SUM(G24:G29) -> 0 | H23: =SUM(H24:H29) -> 0 | I23: =SUM(I24:I29) -> 0 | ... AA23: =SUM(AA24:AA29) -> 0
A24: Venda de Ativos | C24: 0 | E24: 0 | G24: 0 | I24: 0 | K24: 0 | M24: 0 | O24: 0 | Q24: 0 | S24: 0 | U24: 0 | W24: 0 | Y24: 0 | Z24: =B24+D24+F24+H24+J24+L24+N24+P24+R24+T24+V24+X24 -> 0 | AA24: =C24+E24+G24+I24+K24+M24+O24+Q24+S24+U24+W24+Y24 -> 0
A25: Investimentos - DIVERSOS | C25: 0 | E25: 0 | G25: 0 | I25: 0 | K25: 0 | M25: 0 | O25: 0 | Q25: 0 | S25: 0 | U25: 0 | W25: 0 | Y25: 0 | Z25: =B25+D25+F25+H25+J25+L25+N25+P25+R25+T25+V25+X25 -> 0 | AA25: =C25+E25+G25+I25+K25+M25+O25+Q25+S25+U25+W25+Y25 -> 0
A26: Investimentos - IMOBILIZADO | C26: 0 | E26: 0 | G26: 0 | I26: 0 | K26: 0 | M26: 0 | O26: 0 | Q26: 0 | S26: 0 | U26: 0 | W26: 0 | Y26: 0 | Z26: =B26+D26+F26+H26+J26+L26+N26+P26+R26+T26+V26+X26 -> 0 | AA26: =C26+E26+G26+I26+K26+M26+O26+Q26+S26+U26+W26+Y26 -> 0
A27: Aporte de Capital | C27: 0 | E27: 0 | G27: 0 | I27: 0 | K27: 0 | M27: 0 | O27: 0 | Q27: 0 | S27: 0 | U27: 0 | W27: 0 | Y27: 0 | Z27: =B27+D27+F27+H27+J27+L27+N27+P27+R27+T27+V27+X27 -> 0 | AA27: =C27+E27+G27+I27+K27+M27+O27+Q27+S27+U27+W27+Y27 -> 0
A28: Particular | C28: 0 | E28: 0 | G28: 0 | I28: 0 | K28: 0 | M28: 0 | O28: 0 | Q28: 0 | S28: 0 | U28: 0 | W28: 0 | Y28: 0 | Z28: =B28+D28+F28+H28+J28+L28+N28+P28+R28+T28+V28+X28 -> 0 | AA28: =C28+E28+G28+I28+K28+M28+O28+Q28+S28+U28+W28+Y28 -> 0
A29: Pagamento de Dividendos/Lucros | C29: 0 | E29: 0 | G29: 0 | I29: 0 | K29: 0 | M29: 0 | O29: 0 | Q29: 0 | S29: 0 | U29: 0 | W29: 0 | Y29: 0 | Z29: =B29+D29+F29+H29+J29+L29+N29+P29+R29+T29+V29+X29 -> 0 | AA29: =C29+E29+G29+I29+K29+M29+O29+Q29+S29+U29+W29+Y29 -> 0
A30: FLUXO DE CAIXA INVESTIMENTOS | B30: =B23 -> 0 | C30: =C23 -> 0 | D30: =D23 -> 0 | E30: =E23 -> 0 | F30: =F23 -> 0 | G30: =G23 -> 0 | H30: =H23 -> 0 | I30: =I23 -> 0 | ... AA30: =AA23 -> 0
A31: FINANCEIRO | B31: =SUM(B32:B38) -> 0 | C31: =SUM(C32:C38) -> 0 | D31: =SUM(D32:D38) -> 0 | E31: =SUM(E32:E38) -> 0 | F31: =SUM(F32:F38) -> 0 | G31: =SUM(G32:G38) -> 0 | H31: =SUM(H32:H38) -> 0 | I31: =SUM(I32:I38) -> 0 | ... AA31: =SUM(AA32:AA38) -> 0
A32: Captação de Recursos | C32: 0 | E32: 0 | G32: 0 | I32: 0 | K32: 0 | M32: 0 | O32: 0 | Q32: 0 | S32: 0 | U32: 0 | W32: 0 | Y32: 0 | Z32: =B32+D32+F32+H32+J32+L32+N32+P32+R32+T32+V32+X32 -> 0 | AA32: =C32+E32+G32+I32+K32+M32+O32+Q32+S32+U32+W32+Y32 -> 0
A33: Despesas Financeiras (Juros Bancários) | B33: ='DRE PREVISTO'!C63 -> 0 | C33: 0 | D33: ='DRE PREVISTO'!E63 -> 0 | E33: 0 | F33: ='DRE PREVISTO'!G63 -> 0 | G33: 0 | H33: ='DRE PREVISTO'!I63 -> 0 | I33: 0 | J33: ='DRE PREVISTO'!K63 -> 0 | K33: 0 | L33: ='DRE PREVISTO'!M63 -> 0 | M33: 0 | N33: ='DRE PREVISTO'!O63 -> 0 | O33: 0 | P33: ='DRE PREVISTO'!Q63 -> 0 | Q33: 0 | R33: ='DRE PREVISTO'!S63 -> 0 | S33: 0 | T33: ='DRE PREVISTO'!U63 -> 0 | U33: 0 | V33: ='DRE PREVISTO'!W63 -> 0 | W33: 0 | X33: ='DRE PREVISTO'!Y63 -> 0 | Y33: 0 | Z33: =B33+D33+F33+H33+J33+L33+N33+P33+R33+T33+V33+X33 -> 0 | AA33: =C33+E33+G33+I33+K33+M33+O33+Q33+S33+U33+W33+Y33 -> 0
A34: Resgate de Captação | C34: 0 | E34: 0 | G34: 0 | I34: 0 | K34: 0 | M34: 0 | O34: 0 | Q34: 0 | S34: 0 | U34: 0 | W34: 0 | Y34: 0 | Z34: =B34+D34+F34+H34+J34+L34+N34+P34+R34+T34+V34+X34 -> 0 | AA34: =C34+E34+G34+I34+K34+M34+O34+Q34+S34+U34+W34+Y34 -> 0
A35: Aplicações Financeiras | C35: 0 | E35: 0 | G35: 0 | I35: 0 | K35: 0 | M35: 0 | O35: 0 | Q35: 0 | S35: 0 | U35: 0 | W35: 0 | Y35: 0 | Z35: =B35+D35+F35+H35+J35+L35+N35+P35+R35+T35+V35+X35 -> 0 | AA35: =C35+E35+G35+I35+K35+M35+O35+Q35+S35+U35+W35+Y35 -> 0
A36: Amortização Empréstimo - Carros | C36: 0 | E36: 0 | G36: 0 | I36: 0 | K36: 0 | M36: 0 | O36: 0 | Q36: 0 | S36: 0 | U36: 0 | W36: 0 | Y36: 0 | Z36: =B36+D36+F36+H36+J36+L36+N36+P36+R36+T36+V36+X36 -> 0 | AA36: =C36+E36+G36+I36+K36+M36+O36+Q36+S36+U36+W36+Y36 -> 0
A37: Amortizações de Empréstimos Impostos | C37: 0 | E37: 0 | G37: 0 | I37: 0 | K37: 0 | M37: 0 | O37: 0 | Q37: 0 | S37: 0 | U37: 0 | W37: 0 | Y37: 0 | Z37: =B37+D37+F37+H37+J37+L37+N37+P37+R37+T37+V37+X37 -> 0 | AA37: =C37+E37+G37+I37+K37+M37+O37+Q37+S37+U37+W37+Y37 -> 0
A38: Amortizações de Empréstimos - Bancário | C38: 0 | E38: 0 | G38: 0 | I38: 0 | K38: 0 | M38: 0 | O38: 0 | Q38: 0 | S38: 0 | U38: 0 | W38: 0 | Y38: 0 | Z38: =B38+D38+F38+H38+J38+L38+N38+P38+R38+T38+V38+X38 -> 0 | AA38: =C38+E38+G38+I38+K38+M38+O38+Q38+S38+U38+W38+Y38 -> 0
A39: FLUXO DE CAIXA FINANCEIRO | B39: =B31 -> 0 | C39: =C31 -> 0 | D39: =D31 -> 0 | E39: =E31 -> 0 | F39: =F31 -> 0 | G39: =G31 -> 0 | H39: =H31 -> 0 | I39: =I31 -> 0 | ... AA39: =AA31 -> 0
A40: SALDO FINAL | B40: =B7+B22-B30-B39 -> 8513.3487 | C40: =C7+C22-C30-C39 -> 0 | D40: =D7+D22-D30-D39 -> 8768.168 | E40: =E7+E22-E30-E39 -> 0 | F40: =F7+F22-F30-F39 -> 3764.4579 | G40: =G7+G22-G30-G39 -> 0 | H40: =H7+H22-H30-H39 -> 2260.7478 | I40: =I7+I22-I30-I39 -> 0 | ... AA40: =AA7+AA22-AA30-AA39 -> 0

Sheet Planilha1

Sheet DRE  PREVISTO
B1: DRE - DEMONSTRATIVO DE RESULTADOS DO EXERCÍCIO (R$) | AA1: Exercício | AC1: 2025
A3: DESCRIÇÃO | C3: =Parametrização!$F$3 -> 46023 | E3: =Parametrização!$F$4 -> 46054 | G3: =Parametrização!$F$5 -> 46082 | I3: =Parametrização!$F$6 -> 46113 | K3: =Parametrização!$F$7 -> 46143 | M3: =Parametrização!$F$8 -> 46174 | O3: =Parametrização!$F$9 -> 46204 | Q3: =Parametrização!$F$10 -> 46235 | S3: =Parametrização!$F$11 -> 46266 | U3: =Parametrização!$F$12 -> 46296 | W3: =Parametrização!$F$13 -> 46327 | Y3: =Parametrização!$F$14 -> 46357 | AA3: TOTAL DO ANO
C4: =Parametrização!#REF! -> #REF! | D4: =C4 -> #REF! | E4: =Parametrização!#REF! -> #REF! | F4: =E4 -> #REF! | G4: =Parametrização!#REF! -> #REF! | H4: =G4 -> #REF! | I4: =Parametrização!#REF! -> #REF! | J4: =I4 -> #REF! | K4: =Parametrização!#REF! -> #REF! | L4: =K4 -> #REF! | M4: =Parametrização!#REF! -> #REF! | N4: =M4 -> #REF! | O4: =Parametrização!#REF! -> #REF! | P4: =O4 -> #REF! | Q4: =Parametrização!#REF! -> #REF! | R4: =Q4 -> #REF! | S4: =Parametrização!#REF! -> #REF! | T4: =S4 -> #REF! | U4: =Parametrização!#REF! -> #REF! | V4: =U4 -> #REF! | W4: =Parametrização!#REF! -> #REF! | X4: =W4 -> #REF! | Y4: =Parametrização!#REF! -> #REF! | Z4: =Y4 -> #REF!
C5: =Parametrização!#REF! -> #REF! | D5: =C5 -> #REF! | E5: =Parametrização!#REF! -> #REF! | F5: =E5 -> #REF! | G5: =Parametrização!#REF! -> #REF! | H5: =G5 -> #REF! | I5: =Parametrização!#REF! -> #REF! | J5: =I5 -> #REF! | K5: =Parametrização!#REF! -> #REF! | L5: =K5 -> #REF! | M5: =Parametrização!#REF! -> #REF! | N5: =M5 -> #REF! | O5: =Parametrização!#REF! -> #REF! | P5: =O5 -> #REF! | Q5: =Parametrização!#REF! -> #REF! | R5: =Q5 -> #REF! | S5: =Parametrização!#REF! -> #REF! | T5: =S5 -> #REF! | U5: =Parametrização!#REF! -> #REF! | V5: =U5 -> #REF! | W5: =Parametrização!#REF! -> #REF! | X5: =W5 -> #REF! | Y5: =Parametrização!#REF! -> #REF! | Z5: =Y5 -> #REF!
C6: P | D6: R | E6: P | F6: R | G6: P | H6: R | I6: 1600 | J6: R | K6: P | L6: R | M6: P | N6: R | O6: P | P6: R | Q6: P | R6: R | S6: P | T6: R | U6: P | V6: R | W6: P | X6: R | Y6: P | Z6: R | AA6: P | AB6: % | AC6: R | AD6: %
A7: Quantidade | C7: 4000 | D7: 0 | E7: 4500 | F7: 0 | G7: 5000 | H7: 0 | I7: 5000 | J7: 0 | K7: 5000 | L7: 0 | M7: 4000 | N7: 0 | O7: 4000 | P7: 0 | Q7: 5000 | R7: 0 | S7: 5000 | T7: 0 | U7: 5000 | V7: 0 | W7: 5000 | X7: 0 | Y7: 8000 | Z7: 0 | AA7: =C7+E7+G7+I7+K7+M7+O7+Q7+S7+U7+W7+Y7 -> 59500 | AC7: =D7+F7+H7+J7+L7+N7+P7+R7+T7+V7+X7+Z7 -> 0
A8: Preço Médio | C8: 10 | D8: 0 | E8: 10 | F8: 0 | G8: 10 | H8: 0 | I8: 10 | J8: 0 | K8: 10 | L8: 0 | M8: 10 | N8: 0 | O8: 10 | P8: 0 | Q8: 10 | R8: 0 | S8: 10 | T8: 0 | U8: 10 | V8: 0 | W8: 10 | X8: 0 | Y8: 10 | Z8: 0 | AA8: =IFERROR((AA9/AA7),0) -> 10 | AC8: =IFERROR((AC9/AC7),0) -> 0
A9: RECEITA BRUTA | C9: =C7*C8 -> 40000 | D9: =D7*D8 -> 0 | E9: =E7*E8 -> 45000 | F9: =F7*F8 -> 0 | G9: =G7*G8 -> 50000 | H9: =H7*H8 -> 0 | I9: =I7*I8 -> 50000 | J9: =J7*J8 -> 0 | ... Z9: =Z7*Z8 -> 0 | AA9: =C9+E9+G9+I9+K9+M9+O9+Q9+S9+U9+W9+Y9 -> 595000 | AB9: =IFERROR((AA9/$AA$9),0) -> 1 | AC9: =D9+F9+H9+J9+L9+N9+P9+R9+T9+V9+X9+Z9 -> 0 | AD9: =IFERROR((AC9/$AC$9),0) -> 0 | AE9: =+AA9/AA7 -> 10
A10: (-) Deduções de Vendas | B10: =SUM(B11:B14) -> 0.071705882 | C10: =SUM(C11:C14) -> 2868.2353 | D10: =SUM(D11:D14) -> 0 | E10: =SUM(E11:E14) -> 3226.7647 | F10: =SUM(F11:F14) -> 0 | G10: =SUM(G11:G14) -> 3585.2941 | H10: =SUM(H11:H14) -> 0 | I10: =SUM(I11:I14) -> 3585.2941 | ... AA10: =SUM(AA11:AA14) -> 42665 | AB10: =IFERROR((AA10/$AA$9),0) -> 0.071705882 | AC10: =SUM(AC11:AC14) -> 0 | AD10: =IFERROR((AC10/$AC$9),0) -> 0 | AE10: =+AA10/AA9 -> 0.071705882
A11: =Parametrização!B13 -> SIMPLES | B11: =IFERROR((SIMPLES!K8),0) -> 0.071705882 | C11: =C$9*$B11 -> 2868.2353 | D11: =D$9*$B11 -> 0 | E11: =E$9*$B11 -> 3226.7647 | F11: =F$9*$B11 -> 0 | G11: =G$9*$B11 -> 3585.2941 | H11: =H$9*$B11 -> 0 | I11: =I$9*$B11 -> 3585.2941 | J11: =J$9*$B11 -> 0 | ... Z11: =Z$9*$B11 -> 0 | AA11: =C11+E11+G11+I11+K11+M11+O11+Q11+S11+U11+W11+Y11 -> 42665 | AB11: =IFERROR((AA11/$AA$9),0) -> 0.071705882 | AC11: =D11+F11+H11+J11+L11+N11+P11+R11+T11+V11+X11+Z11 -> 0 | AD11: =IFERROR((AC11/$AC$9),0) -> 0
A12: ICMS | B12: 0 | C12: =C$9*$B12 -> 0 | D12: =D$9*$B12 -> 0 | E12: =E$9*$B12 -> 0 | F12: =F$9*$B12 -> 0 | G12: =G$9*$B12 -> 0 | H12: =H$9*$B12 -> 0 | I12: =I$9*$B12 -> 0 | J12: =J$9*$B12 -> 0 | ... Z12: =Z$9*$B12 -> 0 | AA12: =C12+E12+G12+I12+K12+M12+O12+Q12+S12+U12+W12+Y12 -> 0 | AB12: =IFERROR((AA12/$AA$9),0) -> 0 | AC12: =D12+F12+H12+J12+L12+N12+P12+R12+T12+V12+X12+Z12 -> 0 | AD12: =IFERROR((AC12/$AC$9),0) -> 0
A13: PIS | B13: 0 | C13: =C$9*$B13 -> 0 | D13: =D$9*$B13 -> 0 | E13: =E$9*$B13 -> 0 | F13: =F$9*$B13 -> 0 | G13: =G$9*$B13 -> 0 | H13: =H$9*$B13 -> 0 | I13: =I$9*$B13 -> 0 | J13: =J$9*$B13 -> 0 | ... Z13: =Z$9*$B13 -> 0 | AA13: =C13+E13+G13+I13+K13+M13+O13+Q13+S13+U13+W13+Y13 -> 0 | AB13: =IFERROR((AA13/$AA$9),0) -> 0 | AC13: =D13+F13+H13+J13+L13+N13+P13+R13+T13+V13+X13+Z13 -> 0 | AD13: =IFERROR((AC13/$AC$9),0) -> 0
A14: COFINS | B14: 0 | C14: =C$9*$B14 -> 0 | D14: =D$9*$B14 -> 0 | E14: =E$9*$B14 -> 0 | F14: =F$9*$B14 -> 0 | G14: =G$9*$B14 -> 0 | H14: =H$9*$B14 -> 0 | I14: =I$9*$B14 -> 0 | J14: =J$9*$B14 -> 0 | ... Z14: =Z$9*$B14 -> 0 | AA14: =C14+E14+G14+I14+K14+M14+O14+Q14+S14+U14+W14+Y14 -> 0 | AB14: =IFERROR((AA14/$AA$9),0) -> 0 | AC14: =D14+F14+H14+J14+L14+N14+P14+R14+T14+V14+X14+Z14 -> 0 | AD14: =IFERROR((AC14/$AC$9),0) -> 0
